Workbook

Sheet 2025年度出願
A1: kanrino | B1: obscd | C1: obsname | D1: obscd2 | E1: obsname2 | F1: name | G1: namekana | H1: sex | I1: yubin | J1: adres1 | K1: kousdt | L1: nendo | M1: juridt | N1: sktikbn | O1: skatei | P1: scourse | Q1: コース名 | R1: syugyonen | S1: コース系列コード | T1: コース系列名 | U1: 並び順 | V1: kihonno | W1: utiwake | X1: utiwakename | Y1: jitaidt | Z1: suisencd | AA1: kanryodt | AB1: nnendo | AC1: gakuno | AD1: nobscd | AE1: nobsname | AF1: nobscd2 | AG1: nobsname2 | AH1: nktikbn | AI1: nkatei | AJ1: ncourse | AK1: heiganflg | AL1: koucd | AM1: keiei | AN1: kouname | AO1: kencode | AP1: kenname | AQ1: 留学生 | AR1: 書類合否 | AS1: 選考合否 | AT1: kousdt2 | AU1: suisencd2
A2: 2513150002 | B2: 57 | C2: 11_神戸校 | D2: 57 | E2: 4.神戸校 | F2: 棚田 凜香 | G2: ﾀﾅﾀﾞ ﾘﾝｶ | H2: 2 | I2: 672-8070 | J2: 兵庫県 | K2: 2025 | L2: 2025 | M2: 45539 | N2: H04 | O2: 57 | P2: 1756 | Q2: マーケティングビジネス専攻 | R2: 2 | S2: 3 | T2: ビジネス系 | U2: 4 | V2: 2580012 | W2: 0 | Z2: O | AA2: 45573 | AB2: 25 | AC2: 80012 | AD2: 57 | AE2: 11_神戸校 | AF2: 57 | AG2: 4.神戸校 | AH2: H04 | AI2: 57 | AJ2: 1756 | AL2: 28098 | AM2: 県立 | AN2: 姫路商業 | AO2: 28 | AP2: 兵庫 | AQ2: 0 | AR2: Y | AT2: 現役 | AU2: R以外
A3: 2509550072 | B3: 57 | C3: 11_神戸校 | D3: 57 | E3: 4.神戸校 | F3: 田中 ゆら | G3: ﾀﾅｶ ﾕﾗ | H3: 2 | I3: 674-0094 | J3: 兵庫県 | K3: 2025 | L3: 2025 | M3: 45557 | N3: H04 | O3: 0ｼ | P3: 121 | Q3: 医療事務コース | R3: 2 | S3: 8 | T3: 医療事務系 | U3: 6 | V3: 2580016 | W3: 0 | Z3: O | AA3: 45575 | AB3: 25 | AC3: 80016 | AD3: 57 | AE3: 11_神戸校 | AF3: 57 | AG3: 4.神戸校 | AH3: H04 | AI3: 0ｼ | AJ3: 121 | AL3: 28124 | AM3: 市立 | AN3: 明石商業 | AO3: 28 | AP3: 兵庫 | AQ3: 0 | AR3: Y | AT3: 現役 | AU3: R以外
A4: 2505700003 | B4: 57 | C4: 11_神戸校 | D4: 57 | E4: 4.神戸校 | F4: 岩村 琥太郎 | G4: ｲﾜﾑﾗ ｺﾀﾛｳ | H4: 1 | I4: 680-0451 | J4: 鳥取県 | K4: 2025 | L4: 2025 | M4: 45568 | N4: H04 | O4: 0ｽ | P4: 502 | Q4: スポーツトレーナーコース | R4: 2 | S4: 5 | T4: スポーツ系 | U4: 15 | V4: 2580142 | W4: 0 | Z4: S | AA4: 45701 | AB4: 25 | AC4: 80142 | AD4: 57 | AE4: 11_神戸校 | AF4: 57 | AG4: 4.神戸校 | AH4: H04 | AI4: 0ｽ | AJ4: 502 | AL4: 31003 | AM4: 県立 | AN4: 岩美 | AO4: 31 | AP4: 鳥取 | AQ4: 0 | AR4: Y | AT4: 現役 | AU4: R以外
A5: 2505700004 | B5: 57 | C5: 11_神戸校 | D5: 57 | E5: 4.神戸校 | F5: 森田 栄作 | G5: ﾓﾘﾀ ｴｲｻｸ | H5: 1 | I5: 651-2121 | J5: 兵庫県 | K5: 0 | L5: 2025 | M5: 45574 | N5: H04 | O5: 2ｱ | P5: 427 | Q5: 警察官コース | R5: 1 | S5: 2 | T5: 公務員 | U5: 1 | V5: 2580054 | W5: 0 | AA5: 45603 | AB5: 25 | AC5: 80054 | AD5: 57 | AE5: 11_神戸校 | AF5: 57 | AG5: 4.神戸校 | AH5: H04 | AI5: 2ｱ | AJ5: 427 | AL5: 28239 | AM5: 県立 | AN5: 錦城（定時制） | AO5: 28 | AP5: 兵庫 | AQ5: 0 | AR5: Y | AT5: 現役以外 | AU5: R以外
A6: 2505700005 | B6: 57 | C6: 11_神戸校 | D6: 57 | E6: 4.神戸校 | F6: 藤井 柚羽 | G6: ﾌｼﾞｲ ﾕｽﾞﾊ | H6: 2 | I6: 658-0063 | J6: 兵庫県 | K6: 2025 | L6: 2025 | M6: 45589 | N6: H04 | O6: 6 | P6: 448 | Q6: 公認会計士チャレンジコース | R6: 2 | S6: 1 | T6: 税理士会計士系 | U6: 3 | V6: 2580047 | W6: 0 | Z6: Y | AA6: 45602 | AB6: 25 | AC6: 80047 | AD6: 57 | AE6: 11_神戸校 | AF6: 57 | AG6: 4.神戸校 | AH6: H04 | AI6: 6 | AJ6: 448 | AL6: 28224 | AM6: 市立 | AN6: 六甲アイランド | AO6: 28 | AP6: 兵庫 | AQ6: 0 | AR6: Y | AT6: 現役 | AU6: R以外
A7: 2505700006 | B7: 57 | C7: 11_神戸校 | D7: 57 | E7: 4.神戸校 | F7: 中野 太嗣 | G7: ﾅｶﾉ ﾓﾄﾂｸﾞ | H7: 1 | I7: 781-0270 | J7: 高知県 | K7: 2025 | L7: 2025 | M7: 45598 | N7: H04 | O7: 57 | P7: 645 | Q7: 独立経営専攻コース | R7: 2 | S7: 3 | T7: ビジネス系 | U7: 4 | V7: 2580082 | W7: 0 | Z7: S | AA7: 45635 | AB7: 25 | AC7: 80082 | AD7: 57 | AE7: 11_神戸校 | AF7: 57 | AG7: 4.神戸校 | AH7: H04 | AI7: 57 | AJ7: 645 | AL7: 39008 | AM7: 私立 | AN7: 高知 | AO7: 39 | AP7: 高知 | AQ7: 0 | AR7: Y | AT7: 現役 | AU7: R以外
A8: 2505700007 | B8: 57 | C8: 11_神戸校 | D8: 57 | E8: 4.神戸校 | F8: 中谷 夢大 | G8: ﾅｶﾀﾆ ﾕｳﾀﾞｲ | H8: 1 | I8: 653-0811 | J8: 兵庫県 | K8: 2025 | L8: 2025 | M8: 45603 | N8: H04 | O8: 57 | P8: 645 | Q8: 独立経営専攻コース | R8: 2 | S8: 3 | T8: ビジネス系 | U8: 4 | V8: 2580084 | W8: 0 | Z8: S | AA8: 45636 | AB8: 25 | AC8: 80084 | AD8: 57 | AE8: 11_神戸校 | AF8: 57 | AG8: 4.神戸校 | AH8: H04 | AI8: 57 | AJ8: 645 | AL8: 28040 | AM8: 私立 | AN8: 神戸龍谷 | AO8: 28 | AP8: 兵庫 | AQ8: 0 | AR8: Y | AT8: 現役 | AU8: R以外
A9: 2505700008 | B9: 57 | C9: 11_神戸校 | D9: 57 | E9: 4.神戸校 | F9: 石田 龍之介 | G9: ｲｼﾀﾞ ﾘｭｳﾉｽｹ | H9: 1 | I9: 657-0855 | J9: 兵庫県 | K9: 2025 | L9: 2025 | M9: 45612 | N9: H04 | O9: 2ｱ | P9: 428 | Q9: 消防官コース | R9: 1 | S9: 2 | T9: 公務員 | U9: 1 | V9: 2580079 | W9: 0 | Z9: S | AA9: 45631 | AB9: 25 | AC9: 80079 | AD9: 57 | AE9: 11_神戸校 | AF9: 57 | AG9: 4.神戸校 | AH9: H04 | AI9: 2ｱ | AJ9: 428 | AL9: 28233 | AM9: 市立 | AN9: 科学技術 | AO9: 28 | AP9: 兵庫 | AQ9: 0 | AR9: Y | AT9: 現役 | AU9: R以外
A10: 2505700009 | B10: 57 | C10: 11_神戸校 | D10: 57 | E10: 4.神戸校 | F10: 野広 奏 | G10: ﾉﾋﾛ ｶﾅﾃﾞ | H10: 1 | I10: 655-0009 | J10: 兵庫県 | K10: 2025 | L10: 2025 | M10: 45625 | N10: H04 | O10: 2ｱ | P10: 428 | Q10: 消防官コース | R10: 1 | S10: 2 | T10: 公務員 | U10: 1 | V10: 2580090 | W10: 0 | Z10: K | AA10: 45642 | AB10: 25 | AC10: 80090 | AD10: 57 | AE10: 11_神戸校 | AF10: 57 | AG10: 4.神戸校 | AH10: H04 | AI10: 2ｱ | AJ10: 428 | AL10: 28007 | AM10: 県立 | AN10: 舞子 | AO10: 28 | AP10: 兵庫 | AQ10: 0 | AR10: Y | AT10: 現役 | AU10: R以外
A11: 2513150051 | B11: 131 | C11: 17_医療姫路校 | D11: 130 | E11: 7.姫路校 | F11: 上原 優菜 | G11: ｳｴﾊﾗ ﾕｳﾅ | H11: 2 | I11: 671-1143 | J11: 兵庫県 | K11: 2025 | L11: 2025 | M11: 45552 | N11: H04 | O11: 4ｺ | P11: 1044 | Q11: 事務・経理職専攻コース | R11: 2 | S11: 3 | T11: ビジネス系 | U11: 4 | V11: 2522532 | W11: 0 | Z11: O | AA11: 45581 | AB11: 25 | AC11: 22532 | AD11: 131 | AE11: 17_医療姫路校 | AF11: 130 | AG11: 7.姫路校 | AH11: H04 | AI11: 4ｺ | AJ11: 1044 | AL11: 28098 | AM11: 県立 | AN11: 姫路商業 | AO11: 28 | AP11: 兵庫 | AQ11: 0 | AR11: Y | AT11: 現役 | AU11: R以外
A12: 2513150053 | B12: 131 | C12: 17_医療姫路校 | D12: 130 | E12: 7.姫路校 | F12: 置村 さくら | G12: ｵｷﾑﾗ ｻｸﾗ | H12: 2 | I12: 671-1543 | J12: 兵庫県 | K12: 2025 | L12: 2025 | M12: 45582 | N12: H04 | O12: 2ﾕ | P12: 628 | Q12: フィットネストレーナーコース | R12: 2 | S12: 5 | T12: スポーツ系 | U12: 15 | V12: 2522568 | W12: 0 | Z12: O | AA12: 45623 | AB12: 25 | AC12: 22568 | AD12: 131 | AE12: 17_医療姫路校 | AF12: 130 | AG12: 7.姫路校 | AH12: H04 | AI12: 2ﾕ | AJ12: 628 | AL12: 28232 | AM12: 県立 | AN12: 網干（通信制） | AO12: 28 | AP12: 兵庫 | AQ12: 0 | AR12: Y | AT12: 現役 | AU12: R以外
A13: 2513150054 | B13: 131 | C13: 17_医療姫路校 | D13: 130 | E13: 7.姫路校 | F13: 浅尾 美玖 | G13: ｱｻｵ ﾐｸ | H13: 2 | I13: 671-2214 | J13: 兵庫県 | K13: 2025 | L13: 2025 | M13: 45537 | N13: H04 | O13: 7ﾒ | P13: 581 | Q13: ２年制保育士・幼稚園教諭コース | R13: 2 | S13: 10 | T13: 保育系 | U13: 9 | V13: 2522502 | W13: 0 | Z13: O | AA13: 45565 | AB13: 25 | AC13: 22502 | AD13: 131 | AE13: 17_医療姫路校 | AF13: 130 | AG13: 7.姫路校 | AH13: H04 | AI13: 7ﾒ | AJ13: 581 | AL13: 28097 | AM13: 県立 | AN13: 姫路工業 | AO13: 28 | AP13: 兵庫 | AQ13: 0 | AR13: Y | AT13: 現役 | AU13: R以外
A14: 2513150055 | B14: 131 | C14: 17_医療姫路校 | D14: 130 | E14: 7.姫路校 | F14: 名倉 悠大 | G14: ﾅｸﾞﾗ ﾕｳﾀﾞｲ | H14: 1 | I14: 671-2213 | J14: 兵庫県 | K14: 2025 | L14: 2025 | M14: 45537 | N14: H04 | O14: 7ﾒ | P14: 581 | Q14: ２年制保育士・幼稚園教諭コース | R14: 2 | S14: 10 | T14: 保育系 | U14: 9 | V14: 2522522 | W14: 0 | Z14: O | AA14: 45576 | AB14: 25 | AC14: 22522 | AD14: 131 | AE14: 17_医療姫路校 | AF14: 130 | AG14: 7.姫路校 | AH14: H04 | AI14: 7ﾒ | AJ14: 581 | AL14: 28095 | AM14: 私立 | AN14: 東洋大学附属姫路 | AO14: 28 | AP14: 兵庫 | AQ14: 0 | AR14: Y | AT14: 現役 | AU14: R以外
A15: 2513150056 | B15: 131 | C15: 17_医療姫路校 | D15: 130 | E15: 7.姫路校 | F15: 竹中 奏音 | G15: ﾀｹﾅｶ ｶﾉﾝ | H15: 2 | I15: 670-0056 | J15: 兵庫県 | K15: 2025 | L15: 2025 | M15: 45552 | N15: H04 | O15: 4ｺ | P15: 645 | Q15: 独立経営専攻コース | R15: 2 | S15: 3 | T15: ビジネス系 | U15: 4 | V15: 2522534 | W15: 0 | Z15: O | AA15: 45583 | AB15: 25 | AC15: 22534 | AD15: 131 | AE15: 17_医療姫路校 | AF15: 130 | AG15: 7.姫路校 | AH15: H04 | AI15: 4ｺ | AJ15: 645 | AL15: 28255 | AM15: 私立 | AN15: おおぞら高等学院姫路キャンパス | AO15: 28 | AP15: 兵庫 | AQ15: 0 | AR15: Y | AT15: 現役 | AU15: R以外
A16: 2513150059 | B16: 131 | C16: 17_医療姫路校 | D16: 130 | E16: 7.姫路校 | F16: 石田 さくら | G16: ｲｼﾀﾞ ｻｸﾗ | H16: 2 | I16: 671-1201 | J16: 兵庫県 | K16: 2025 | L16: 2025 | M16: 45586 | N16: H04 | O16: 4ｺ | P16: 1044 | Q16: 事務・経理職専攻コース | R16: 2 | S16: 3 | T16: ビジネス系 | U16: 4 | V16: 2522558 | W16: 0 | Z16: O | AA16: 45607 | AB16: 25 | AC16: 22558 | AD16: 131 | AE16: 17_医療姫路校 | AF16: 130 | AG16: 7.姫路校 | AH16: H04 | AI16: 4ｺ | AJ16: 1044 | AL16: 28283 | AM16: 私立 | AN16: 鹿島朝日高等学校 姫路キャンパス | AO16: 28 | AP16: 兵庫 | AQ16: 0 | AR16: Y | AT16: 現役 | AU16: R以外
A17: 2513150061 | B17: 131 | C17: 17_医療姫路校 | D17: 130 | E17: 7.姫路校 | F17: 塚本 琉以 | G17: ﾂｶﾓﾄ ﾙｲ | H17: 1 | I17: 671-2517 | J17: 兵庫県 | K17: 2025 | L17: 2025 | M17: 45589 | N17: H04 | O17: 7ﾗ | P17: 260 | Q17: 公務員＆民間就職コース | R17: 2 | S17: 2 | T17: 公務員 | U17: 1 | V17: 2522553 | W17: 0 | Z17: O | AA17: 45602 | AB17: 25 | AC17: 22553 | AD17: 131 | AE17: 17_医療姫路校 | AF17: 130 | AG17: 7.姫路校 | AH17: H04 | AI17: 7ﾗ | AJ17: 260 | AL17: 28168 | AM17: 県立 | AN17: 山崎 | AO17: 28 | AP17: 兵庫 | AQ17: 0 | AR17: Y | AT17: 現役 | AU17: R以外
A18: 2513150062 | B18: 131 | C18: 17_医療姫路校 | D18: 130 | E18: 7.姫路校 | F18: 小国 奏 | G18: ｵｸﾞﾆ ｶﾅﾃﾞ | H18: 2 | I18: 679-4016 | J18: 兵庫県 | K18: 2025 | L18: 2025 | M18: 45593 | N18: H04 | O18: 7ﾗ | P18: 968 | Q18: 市役所・町役場等初級レベル | R18: 2 | S18: 2 | T18: 公務員 | U18: 1 | V18: 2522587 | W18: 0 | Z18: O | AA18: 45672 | AB18: 25 | AC18: 22587 | AD18: 131 | AE18: 17_医療姫路校 | AF18: 130 | AG18: 7.姫路校 | AH18: H04 | AI18: 7ﾗ | AJ18: 968 | AL18: 28017 | AM18: 私立 | AN18: 神戸常盤女子 | AO18: 28 | AP18: 兵庫 | AQ18: 0 | AR18: Y | AT18: 現役 | AU18: R以外
A19: 2513150064 | B19: 131 | C19: 17_医療姫路校 | D19: 130 | E19: 7.姫路校 | F19: 千本 健翔 | G19: ﾁﾓﾄ ｹﾝｼｮｳ | H19: 1 | I19: 671-2542 | J19: 兵庫県 | K19: 2025 | L19: 2025 | M19: 45554 | N19: H04 | O19: 7ﾗ | P19: 428 | Q19: 消防官コース | R19: 2 | S19: 2 | T19: 公務員 | U19: 1 | V19: 0 | W19: 0 | Y19: 45609 | Z19: O | AB19: 0 | AC19: 0 | AD19: 0 | AE19: 0_未手続 | AG19: 0_未手続 | AJ19: 0 | AK19: K | AL19: 28169 | AM19: 県立 | AN19: 千種 | AO19: 28 | AP19: 兵庫 | AQ19: 0 | AR19: Y | AT19: 現役 | AU19: R以外
A20: 2513150065 | B20: 131 | C20: 17_医療姫路校 | D20: 130 | E20: 7.姫路校 | F20: 飯田 夏実 | G20: ｲｲﾀﾞ ﾅﾂﾐ | H20: 2 | I20: 671-4122 | J20: 兵庫県 | K20: 2025 | L20: 2025 | M20: 45552 | N20: H04 | O20: 4ｺ | P20: 1044 | Q20: 事務・経理職専攻コース | R20: 2 | S20: 3 | T20: ビジネス系 | U20: 4 | V20: 2522542 | W20: 0 | Z20: O | AA20: 45595 | AB20: 25 | AC20: 22542 | AD20: 131 | AE20: 17_医療姫路校 | AF20: 130 | AG20: 7.姫路校 | AH20: H04 | AI20: 4ｺ | AJ20: 1044 | AL20: 28170 | AM20: 県立 | AN20: 伊和 | AO20: 28 | AP20: 兵庫 | AQ20: 0 | AR20: Y | AT20: 現役 | AU20: R以外
A21: 2513150066 | B21: 131 | C21: 17_医療姫路校 | D21: 130 | E21: 7.姫路校 | F21: 大谷 謙心 | G21: ｵｵﾀﾆ ｹﾝｼﾝ | H21: 1 | I21: 672-8082 | J21: 兵庫県 | K21: 2025 | L21: 2025 | M21: 45544 | N21: H04 | O21: 2ﾕ | P21: 502 | Q21: スポーツトレーナーコース | R21: 2 | S21: 5 | T21: スポーツ系 | U21: 15 | V21: 2522528 | W21: 0 | Z21: O | AA21: 45580 | AB21: 25 | AC21: 22528 | AD21: 131 | AE21: 17_医療姫路校 | AF21: 130 | AG21: 7.姫路校 | AH21: H04 | AI21: 2ﾕ | AJ21: 502 | AL21: 28095 | AM21: 私立 | AN21: 東洋大学附属姫路 | AO21: 28 | AP21: 兵庫 | AQ21: 0 | AR21: Y | AT21: 現役 | AU21: R以外
A22: 2513150067 | B22: 131 | C22: 17_医療姫路校 | D22: 130 | E22: 7.姫路校 | F22: 石田 叶禄 | G22: ｲｼﾀﾞ ｶﾛｸ | H22: 1 | I22: 671-2244 | J22: 兵庫県 | K22: 2025 | L22: 2025 | M22: 45548 | N22: H04 | O22: 2ﾕ | P22: 502 | Q22: スポーツトレーナーコース | R22: 2 | S22: 5 | T22: スポーツ系 | U22: 15 | V22: 2522523 | W22: 166 | X22: アスリートフード専攻 | Z22: O | AA22: 45580 | AB22: 25 | AC22: 22523 | AD22: 131 | AE22: 17_医療姫路校 | AF22: 130 | AG22: 7.姫路校 | AH22: H04 | AI22: 2ﾕ | AJ22: 502 | AL22: 28095 | AM22: 私立 | AN22: 東洋大学附属姫路 | AO22: 28 | AP22: 兵庫 | AQ22: 0 | AR22: Y | AT22: 現役 | AU22: R以外
A23: 2513150068 | B23: 131 | C23: 17_医療姫路校 | D23: 130 | E23: 7.姫路校 | F23: 岡本 康生 | G23: ｵｶﾓﾄ ｺｳｾｲ | H23: 1 | I23: 672-8043 | J23: 兵庫県 | K23: 2025 | L23: 2025 | M23: 45538 | N23: H04 | O23: 7ﾒ | P23: 581 | Q23: ２年制保育士・幼稚園教諭コース | R23: 2 | S23: 10 | T23: 保育系 | U23: 9 | V23: 2522512 | W23: 0 | Z23: O | AA23: 45568 | AB23: 25 | AC23: 22512 | AD23: 131 | AE23: 17_医療姫路校 | AF23: 130 | AG23: 7.姫路校 | AH23: H04 | AI23: 7ﾒ | AJ23: 581 | AL23: 28247 | AM23: 県立 | AN23: 龍野北 | AO23: 28 | AP23: 兵庫 | AQ23: 0 | AR23: Y | AT23: 現役 | AU23: R以外
A24: 2513150069 | B24: 131 | C24: 17_医療姫路校 | D24: 130 | E24: 7.姫路校 | F24: 中川 弥音 | G24: ﾅｶｶﾞﾜ ﾐｵﾄ | H24: 2 | I24: 700-0831 | J24: 岡山県 | K24: 2025 | L24: 2025 | M24: 45572 | N24: H04 | O24: 7ﾒ | P24: 581 | Q24: ２年制保育士・幼稚園教諭コース | R24: 2 | S24: 10 | T24: 保育系 | U24: 9 | V24: 0 | W24: 0 | Y24: 45678 | Z24: O | AB24: 0 | AC24: 0 | AD24: 0 | AE24: 0_未手続 | AG24: 0_未手続 | AJ24: 0 | AK24: Y | AL24: 33018 | AM24: 県立 | AN24: 岡山南 | AO24: 33 | AP24: 岡山 | AQ24: 0 | AR24: Y | AT24: 現役 | AU24: R以外
A25: 2513150070 | B25: 131 | C25: 17_医療姫路校 | D25: 130 | E25: 7.姫路校 | F25: 伊藤 瑛那 | G25: ｲﾄｳ ｱｷﾅ | H25: 2 | I25: 671-4105 | J25: 兵庫県 | K25: 2025 | L25: 2025 | M25: 45541 | N25: H04 | O25: 7ﾒ | P25: 1680 | Q25: ２年制こども保育士コース | R25: 2 | S25: 10 | T25: 保育系 | U25: 9 | V25: 2522597 | W25: 0 | Z25: O | AA25: 45688 | AB25: 25 | AC25: 22597 | AD25: 131 | AE25: 17_医療姫路校 | AF25: 130 | AG25: 7.姫路校 | AH25: H04 | AI25: 7ﾒ | AJ25: 1680 | AL25: 28168 | AM25: 県立 | AN25: 山崎 | AO25: 28 | AP25: 兵庫 | AQ25: 0 | AR25: Y | AT25: 現役 | AU25: R以外
A26: 2513150071 | B26: 131 | C26: 17_医療姫路校 | D26: 130 | E26: 7.姫路校 | F26: 浅見 航輝 | G26: ｱｻﾐ ｺｳｷ | H26: 1 | I26: 671-0101 | J26: 兵庫県 | K26: 2025 | L26: 2025 | M26: 45552 | N26: H04 | O26: 4ｺ | P26: 969 | Q26: ＩＴビジネス専攻コース | R26: 2 | S26: 3 | T26: ビジネス系 | U26: 4 | V26: 2522527 | W26: 0 | Z26: O | AA26: 45580 | AB26: 25 | AC26: 22527 | AD26: 131 | AE26: 17_医療姫路校 | AF26: 130 | AG26: 7.姫路校 | AH26: H04 | AI26: 4ｺ | AJ26: 969 | AL26: 28330 | AM26: 私立 | AN26: Ｎ高等学校 姫路キャンパス | AO26: 28 | AP26: 兵庫 | AQ26: 0 | AR26: Y | AT26: 現役 | AU26: R以外
A27: 2513150072 | B27: 131 | C27: 17_医療姫路校 | D27: 130 | E27: 7.姫路校 | F27: 田淵 雄希 | G27: ﾀﾌﾞﾁ ﾕｳｷ | H27: 1 | I27: 674-0091 | J27: 兵庫県 | K27: 2025 | L27: 2025 | M27: 45544 | N27: H04 | O27: 7ﾘ | P27: 427 | Q27: 警察官コース | R27: 1 | S27: 2 | T27: 公務員 | U27: 1 | V27: 0 | W27: 0 | Y27: 45572 | Z27: O | AB27: 0 | AC27: 0 | AD27: 0 | AE27: 0_未手続 | AG27: 0_未手続 | AJ27: 0 | AK27: K | AL27: 28185 | AM27: 県立 | AN27: 明石清水 | AO27: 28 | AP27: 兵庫 | AQ27: 0 | AR27: Y | AT27: 現役 | AU27: R以外
A28: 2513150073 | B28: 131 | C28: 17_医療姫路校 | D28: 130 | E28: 7.姫路校 | F28: 宮﨑 夏帆 | G28: ﾐﾔｻﾞｷ ｶﾎ | H28: 2 | I28: 679-2414 | J28: 兵庫県 | K28: 2025 | L28: 2025 | M28: 45537 | N28: H04 | O28: 2ﾕ | P28: 870 | Q28: こどもスポーツコース | R28: 2 | S28: 5 | T28: スポーツ系 | U28: 15 | V28: 2522513 | W28: 0 | Z28: O | AA28: 45572 | AB28: 25 | AC28: 22513 | AD28: 131 | AE28: 17_医療姫路校 | AF28: 130 | AG28: 7.姫路校 | AH28: H04 | AI28: 2ﾕ | AJ28: 870 | AL28: 28098 | AM28: 県立 | AN28: 姫路商業 | AO28: 28 | AP28: 兵庫 | AQ28: 0 | AR28: Y | AT28: 現役 | AU28: R以外
A29: 2513150074 | B29: 131 | C29: 17_医療姫路校 | D29: 130 | E29: 7.姫路校 | F29: 福本 匠真 | G29: ﾌｸﾓﾄ ﾀｸﾏ | H29: 1 | I29: 672-8083 | J29: 兵庫県 | K29: 2025 | L29: 2025 | M29: 45544 | N29: H04 | O29: 2ﾕ | P29: 502 | Q29: スポーツトレーナーコース | R29: 2 | S29: 5 | T29: スポーツ系 | U29: 15 | V29: 2522580 | W29: 0 | Z29: O | AA29: 45649 | AB29: 25 | AC29: 22580 | AD29: 131 | AE29: 17_医療姫路校 | AF29: 130 | AG29: 7.姫路校 | AH29: H04 | AI29: 2ﾕ | AJ29: 502 | AL29: 28094 | AM29: 私立 | AN29: 市川 | AO29: 28 | AP29: 兵庫 | AQ29: 0 | AR29: Y | AT29: 現役 | AU29: R以外
A30: 2513150075 | B30: 131 | C30: 17_医療姫路校 | D30: 130 | E30: 7.姫路校 | F30: 萬谷 陸 | G30: ﾏﾝﾀﾆ ﾘｸ | H30: 1 | I30: 671-0111 | J30: 兵庫県 | K30: 2025 | L30: 2025 | M30: 45568 | N30: H04 | O30: 2ﾕ | P30: 502 | Q30: スポーツトレーナーコース | R30: 2 | S30: 5 | T30: スポーツ系 | U30: 15 | V30: 2522579 | W30: 0 | Z30: O | AA30: 45649 | AB30: 25 | AC30: 22579 | AD30: 131 | AE30: 17_医療姫路校 | AF30: 130 | AG30: 7.姫路校 | AH30: H04 | AI30: 2ﾕ | AJ30: 502 | AL30: 28157 | AM30: 市立 | AN30: 飾磨 | AO30: 28 | AP30: 兵庫 | AQ30: 0 | AR30: Y | AT30: 現役 | AU30: R以外
A31: 2513150076 | B31: 131 | C31: 17_医療姫路校 | D31: 130 | E31: 7.姫路校 | F31: 向島 達也 | G31: ﾑｺｳｼﾞﾏ ﾀﾂﾔ | H31: 1 | I31: 670-0996 | J31: 兵庫県 | K31: 2025 | L31: 2025 | M31: 45572 | N31: H04 | O31: 4ｺ | P31: 1044 | Q31: 事務・経理職専攻コース | R31: 2 | S31: 3 | T31: ビジネス系 | U31: 4 | V31: 2522600 | W31: 0 | Z31: O | AA31: 45692 | AB31: 25 | AC31: 22600 | AD31: 131 | AE31: 17_医療姫路校 | AF31: 130 | AG31: 7.姫路校 | AH31: H04 | AI31: 4ｺ | AJ31: 1044 | AL31: 28240 | AM31: 県立 | AN31: 姫路北（定時制） | AO31: 28 | AP31: 兵庫 | AQ31: 0 | AR31: Y | AT31: 現役 | AU31: R以外
A32: 2513150077 | B32: 131 | C32: 17_医療姫路校 | D32: 130 | E32: 7.姫路校 | F32: 地神 和 | G32: ﾁｶﾞﾐ ﾉﾄﾞｶ | H32: 2 | I32: 675-0021 | J32: 兵庫県 | K32: 2025 | L32: 2025 | M32: 45572 | N32: H04 | O32: 7ﾘ | P32: 427 | Q32: 警察官コース | R32: 1 | S32: 2 | T32: 公務員 | U32: 1 | V32: 0 | W32: 0 | Y32: 45671 | Z32: O | AB32: 0 | AC32: 0 | AD32: 0 | AE32: 0_未手続 | AG32: 0_未手続 | AJ32: 0 | AK32: K | AL32: 28193 | AM32: 県立 | AN32: 高砂南 | AO32: 28 | AP32: 兵庫 | AQ32: 0 | AR32: Y | AT32: 現役 | AU32: R以外
A33: 2513150080 | B33: 131 | C33: 17_医療姫路校 | D33: 130 | E33: 7.姫路校 | F33: 杉岡 凰太 | G33: ｽｷﾞｵｶ ｺｳﾀ | H33: 1 | I33: 719-0302 | J33: 岡山県 | K33: 2025 | L33: 2025 | M33: 45567 | N33: H04 | O33: 2ﾕ | P33: 112 | Q33: スポーツインストラクターコース | R33: 2 | S33: 5 | T33: スポーツ系 | U33: 15 | V33: 2522584 | W33: 0 | Z33: O | AA33: 45667 | AB33: 25 | AC33: 22584 | AD33: 131 | AE33: 17_医療姫路校 | AF33: 130 | AG33: 7.姫路校 | AH33: H04 | AI33: 2ﾕ | AJ33: 112 | AL33: 33076 | AM33: 私立 | AN33: 岡山龍谷 | AO33: 33 | AP33: 岡山 | AQ33: 0 | AR33: Y | AT33: 現役 | AU33: R以外
A34: 2513150082 | B34: 131 | C34: 17_医療姫路校 | D34: 130 | E34: 7.姫路校 | F34: 林 英汰 | G34: ﾊﾔｼ ｴｲﾀ | H34: 1 | I34: 670-0947 | J34: 兵庫県 | K34: 2025 | L34: 2025 | M34: 45596 | N34: H04 | O34: 7ﾘ | P34: 427 | Q34: 警察官コース | R34: 1 | S34: 2 | T34: 公務員 | U34: 1 | V34: 0 | W34: 0 | Y34: 45672 | Z34: O | AB34: 0 | AC34: 0 | AD34: 0 | AE34: 0_未手続 | AG34: 0_未手続 | AJ34: 0 | AK34: K | AL34: 28098 | AM34: 県立 | AN34: 姫路商業 | AO34: 28 | AP34: 兵庫 | AQ34: 0 | AR34: Y | AT34: 現役 | AU34: R以外
A35: 2513150084 | B35: 131 | C35: 17_医療姫路校 | D35: 130 | E35: 7.姫路校 | F35: 小野 夏碧 | G35: ｵﾉ ﾅﾂﾐ | H35: 2 | I35: 671-1573 | J35: 兵庫県 | K35: 2025 | L35: 2025 | M35: 45573 | N35: H04 | O35: 7ﾗ | P35: 785 | Q35: 学校事務・警察事務職員コース | R35: 2 | S35: 2 | T35: 公務員 | U35: 1 | V35: 0 | W35: 0 | Y35: 45614 | Z35: O | AB35: 0 | AC35: 0 | AD35: 0 | AE35: 0_未手続 | AG35: 0_未手続 | AJ35: 0 | AK35: K | AL35: 28177 | AM35: 県立 | AN35: 姫路南 | AO35: 28 | AP35: 兵庫 | AQ35: 0 | AR35: Y | AT35: 現役 | AU35: R以外
A36: 2513150085 | B36: 131 | C36: 17_医療姫路校 | D36: 130 | E36: 7.姫路校 | F36: 竹山 羽琉 | G36: ﾀｹﾔﾏ ﾊﾙ | H36: 1 | I36: 678-0091 | J36: 兵庫県 | K36: 2025 | L36: 2025 | M36: 45588 | N36: H04 | O36: 7ﾗ | P36: 968 | Q36: 市役所・町役場等初級レベル | R36: 2 | S36: 2 | T36: 公務員 | U36: 1 | V36: 0 | W36: 0 | Y36: 45729 | Z36: O | AB36: 0 | AC36: 0 | AD36: 0 | AE36: 0_未手続 | AG36: 0_未手続 | AJ36: 0 | AK36: K | AL36: 28178 | AM36: 県立 | AN36: 太子 | AO36: 28 | AP36: 兵庫 | AQ36: 0 | AR36: Y | AT36: 現役 | AU36: R以外
A37: 2513150086 | B37: 131 | C37: 17_医療姫路校 | D37: 130 | E37: 7.姫路校 | F37: 平岡 圭人 | G37: ﾋﾗｵｶ ｹｲﾄ | H37: 1 | I37: 679-4008 | J37: 兵庫県 | K37: 2025 | L37: 2025 | M37: 45559 | N37: H04 | O37: 4ｺ | P37: 1756 | Q37: マーケティングビジネス専攻 | R37: 2 | S37: 3 | T37: ビジネス系 | U37: 4 | V37: 2522520 | W37: 0 | Z37: O | AA37: 45576 | AB37: 25 | AC37: 22520 | AD37: 131 | AE37: 17_医療姫路校 | AF37: 130 | AG37: 7.姫路校 | AH37: H04 | AI37: 4ｺ | AJ37: 1756 | AL37: 28178 | AM37: 県立 | AN37: 太子 | AO37: 28 | AP37: 兵庫 | AQ37: 0 | AR37: Y | AT37: 現役 | AU37: R以外
A38: 2513150087 | B38: 131 | C38: 17_医療姫路校 | D38: 130 | E38: 7.姫路校 | F38: 長尾 想 | G38: ﾅｶﾞｵ ｺｺﾛ | H38: 2 | I38: 676-0082 | J38: 兵庫県 | K38: 2025 | L38: 2025 | M38: 45544 | N38: H04 | O38: 2ﾕ | P38: 112 | Q38: スポーツインストラクターコース | R38: 2 | S38: 5 | T38: スポーツ系 | U38: 15 | V38: 2522607 | W38: 0 | Z38: O | AA38: 45708 | AB38: 25 | AC38: 22607 | AD38: 131 | AE38: 17_医療姫路校 | AF38: 130 | AG38: 7.姫路校 | AH38: H04 | AI38: 2ﾕ | AJ38: 112 | AL38: 28107 | AM38: 県立 | AN38: 松陽 | AO38: 28 | AP38: 兵庫 | AQ38: 0 | AR38: Y | AT38: 現役 | AU38: R以外
A39: 2513150088 | B39: 131 | C39: 17_医療姫路校 | D39: 130 | E39: 7.姫路校 | F39: 吉田 真雪 | G39: ﾖｼﾀﾞ ﾏﾕ | H39: 2 | I39: 671-1102 | J39: 兵庫県 | K39: 2025 | L39: 2025 | M39: 45586 | N39: H04 | O39: 7ﾒ | P39: 581 | Q39: ２年制保育士・幼稚園教諭コース | R39: 2 | S39: 10 | T39: 保育系 | U39: 9 | V39: 2522560 | W39: 0 | Z39: O | AA39: 45607 | AB39: 25 | AC39: 22560 | AD39: 131 | AE39: 17_医療姫路校 | AF39: 130 | AG39: 7.姫路校 | AH39: H04 | AI39: 7ﾒ | AJ39: 581 | AL39: 28107 | AM39: 県立 | AN39: 松陽 | AO39: 28 | AP39: 兵庫 | AQ39: 0 | AR39: Y | AT39: 現役 | AU39: R以外
A40: 2513150090 | B40: 131 | C40: 17_医療姫路校 | D40: 130 | E40: 7.姫路校 | F40: 柿原 洸太 | G40: ｶｷﾊﾗ ｺｳﾀ | H40: 1 | I40: 674-0094 | J40: 兵庫県 | K40: 2025 | L40: 2025 | M40: 45555 | N40: H04 | O40: 7ﾗ | P40: 428 | Q40: 消防官コース | R40: 2 | S40: 2 | T40: 公務員 | U40: 1 | V40: 0 | W40: 0 | Y40: 45716 | Z40: O | AB40: 0 | AC40: 0 | AD40: 0 | AE40: 0_未手続 | AG40: 0_未手続 | AJ40: 0 | AK40: K | AL40: 28107 | AM40: 県立 | AN40: 松陽 | AO40: 28 | AP40: 兵庫 | AQ40: 0 | AR40: Y | AT40: 現役 | AU40: R以外
...

Sheet 2026年度出願
A1: kanrino | B1: obscd | C1: obsname | D1: obscd2 | E1: obsname2 | F1: name | G1: namekana | H1: sex | I1: yubin | J1: adres1 | K1: kousdt | L1: nendo | M1: juridt | N1: sktikbn | O1: skatei | P1: scourse | Q1: コース名 | R1: syugyonen | S1: コース系列コード | T1: コース系列名 | U1: 並び順 | V1: kihonno | W1: utiwake | X1: utiwakename | Y1: jitaidt | Z1: suisencd | AA1: kanryodt | AB1: nnendo | AC1: gakuno | AD1: nobscd | AE1: nobsname | AF1: nobscd2 | AG1: nobsname2 | AH1: nktikbn | AI1: nkatei | AJ1: ncourse | AK1: heiganflg | AL1: koucd | AM1: keiei | AN1: kouname | AO1: kencode | AP1: kenname | AQ1: 留学生 | AR1: 書類合否 | AS1: 選考合否 | AT1: kousdt2 | AU1: suisencd2
A2: 2605700001 | B2: 57 | C2: 11_神戸校 | D2: 57 | E2: 4.神戸校 | F2: 三井 虎太郎 | G2: ﾐﾂｲ ｺﾀﾛｳ | H2: 1 | I2: 651-1103 | J2: 兵庫県 | K2: 2026 | L2: 2026 | M2: 45931 | N2: H04 | O2: 58 | P2: 968 | Q2: 市役所・町役場等初級レベル | R2: 2 | S2: 2 | T2: 公務員 | U2: 1 | V2: 2680027 | W2: 0 | AA2: 45951 | AB2: 26 | AC2: 80027 | AD2: 57 | AE2: 11_神戸校 | AF2: 57 | AG2: 4.神戸校 | AH2: H04 | AI2: 58 | AJ2: 968 | AL2: 28009 | AM2: 県立 | AN2: 神戸甲北 | AO2: 28 | AP2: 兵庫 | AQ2: 0 | AR2: Y | AT2: 現役 | AU2: R以外
A3: 2605700002 | B3: 57 | C3: 11_神戸校 | D3: 57 | E3: 4.神戸校 | F3: 藤岡 衣咲 | G3: ﾌｼﾞｵｶ ｲｻｷ | H3: 2 | I3: 673-0423 | J3: 兵庫県 | K3: 2026 | L3: 2026 | M3: 45937 | N3: H04 | O3: 0ｼ | P3: 121 | Q3: 医療事務コース | R3: 2 | S3: 8 | T3: 医療事務系 | U3: 6 | V3: 2680030 | W3: 0 | Z3: V | AA3: 45953 | AB3: 26 | AC3: 80030 | AD3: 57 | AE3: 11_神戸校 | AF3: 57 | AG3: 4.神戸校 | AH3: H04 | AI3: 0ｼ | AJ3: 121 | AL3: 28120 | AM3: 県立 | AN3: 三木東 | AO3: 28 | AP3: 兵庫 | AQ3: 0 | AR3: Y | AT3: 現役 | AU3: R以外
A4: 2605700003 | B4: 57 | C4: 11_神戸校 | D4: 57 | E4: 4.神戸校 | F4: 中村 慶太 | G4: ﾅｶﾑﾗ ｹｲﾀ | H4: 1 | I4: 658-0015 | J4: 兵庫県 | K4: 2026 | L4: 2026 | M4: 45937 | N4: H04 | O4: 58 | P4: 427 | Q4: 警察官コース | R4: 2 | S4: 2 | T4: 公務員 | U4: 1 | V4: 2680058 | W4: 0 | Z4: V | AA4: 45981 | AB4: 26 | AC4: 80058 | AD4: 57 | AE4: 11_神戸校 | AF4: 57 | AG4: 4.神戸校 | AH4: H04 | AI4: 58 | AJ4: 427 | AL4: 28282 | AM4: 市立 | AN4: 神港橘 | AO4: 28 | AP4: 兵庫 | AQ4: 0 | AR4: Y | AT4: 現役 | AU4: R以外
A5: 2605700004 | B5: 57 | C5: 11_神戸校 | D5: 57 | E5: 4.神戸校 | F5: 福田 悠叶 | G5: ﾌｸﾀﾞ ﾕｳﾄ | H5: 1 | I5: 654-0152 | J5: 兵庫県 | K5: 2026 | L5: 2026 | M5: 45937 | N5: H04 | O5: 6 | P5: 488 | Q5: 公認会計士スタンダードコース | R5: 2 | S5: 1 | T5: 税理士会計士系 | U5: 3 | V5: 2680125 | W5: 0 | Z5: T | AA5: 46035 | AB5: 26 | AC5: 80125 | AD5: 57 | AE5: 11_神戸校 | AF5: 57 | AG5: 4.神戸校 | AH5: H04 | AI5: 6 | AJ5: 488 | AL5: 28030 | AM5: 県立 | AN5: 神戸商業 | AO5: 28 | AP5: 兵庫 | AQ5: 0 | AR5: Y | AT5: 現役 | AU5: R以外
A6: 2600350083 | B6: 57 | C6: 11_神戸校 | D6: 57 | E6: 4.神戸校 | F6: 篠原 百々花 | G6: ｼﾉﾊﾗ ﾓﾓｶ | H6: 2 | I6: 650-0002 | J6: 兵庫県 | K6: 2026 | L6: 2026 | M6: 45959 | N6: H04 | O6: 57 | P6: 1044 | Q6: 事務・経理職専攻コース | R6: 2 | S6: 3 | T6: ビジネス系 | U6: 4 | V6: 2680092 | W6: 0 | Z6: O | AA6: 46010 | AB6: 26 | AC6: 80092 | AD6: 57 | AE6: 11_神戸校 | AF6: 57 | AG6: 4.神戸校 | AH6: H04 | AI6: 57 | AJ6: 1044 | AK6: Y | AL6: 28282 | AM6: 市立 | AN6: 神港橘 | AO6: 28 | AP6: 兵庫 | AQ6: 0 | AR6: Y | AT6: 現役 | AU6: R以外
A7: 2605700006 | B7: 57 | C7: 11_神戸校 | D7: 57 | E7: 4.神戸校 | F7: 山本 涼晴 | G7: ﾔﾏﾓﾄ ｽｽﾞﾊ | H7: 2 | I7: 671-0122 | J7: 兵庫県 | K7: 2026 | L7: 2026 | M7: 45961 | N7: H04 | O7: 7 | P7: 266 | Q7: 税理士スタンダードコース | R7: 2 | S7: 1 | T7: 税理士会計士系 | U7: 3 | V7: 0 | W7: 0 | AB7: 0 | AC7: 0 | AD7: 0 | AE7: 0_未手続 | AG7: 0_未手続 | AJ7: 0 | AK7: Y | AL7: 28204 | AM7: 県立 | AN7: 明石城西 | AO7: 28 | AP7: 兵庫 | AQ7: 0 | AR7: Y | AT7: 現役 | AU7: R以外
A8: 2605700007 | B8: 57 | C8: 11_神戸校 | D8: 57 | E8: 4.神戸校 | F8: 北山 世尚 | G8: ｷﾀﾔﾏ ｾﾅ | H8: 1 | I8: 675-1359 | J8: 兵庫県 | K8: 2026 | L8: 2026 | M8: 45970 | N8: H04 | O8: 2ｱ | P8: 428 | Q8: 消防官コース | R8: 1 | S8: 2 | T8: 公務員 | U8: 1 | V8: 2680064 | W8: 0 | Z8: V | AA8: 45987 | AB8: 26 | AC8: 80064 | AD8: 57 | AE8: 11_神戸校 | AF8: 57 | AG8: 4.神戸校 | AH8: H04 | AI8: 2ｱ | AJ8: 428 | AL8: 28137 | AM8: 県立 | AN8: 社 | AO8: 28 | AP8: 兵庫 | AQ8: 0 | AR8: Y | AT8: 現役 | AU8: R以外
A9: 2605700008 | B9: 57 | C9: 11_神戸校 | D9: 57 | E9: 4.神戸校 | F9: 谷口 依武紀 | G9: ﾀﾆｸﾞﾁ ｲﾌﾞｷ | H9: 1 | I9: 651-2124 | J9: 兵庫県 | K9: 2026 | L9: 2026 | M9: 45974 | N9: H04 | O9: 58 | P9: 428 | Q9: 消防官コース | R9: 2 | S9: 2 | T9: 公務員 | U9: 1 | V9: 2680088 | W9: 0 | Z9: V | AA9: 46008 | AB9: 26 | AC9: 80088 | AD9: 57 | AE9: 11_神戸校 | AF9: 57 | AG9: 4.神戸校 | AH9: H04 | AI9: 58 | AJ9: 428 | AL9: 28185 | AM9: 県立 | AN9: 明石清水 | AO9: 28 | AP9: 兵庫 | AQ9: 0 | AR9: Y | AT9: 現役 | AU9: R以外
A10: 2605700009 | B10: 57 | C10: 11_神戸校 | D10: 57 | E10: 4.神戸校 | F10: 緒方 瑛信 | G10: ｵｶﾞﾀ ｴｲｼﾝ | H10: 1 | I10: 654-0103 | J10: 兵庫県 | K10: 2026 | L10: 2026 | M10: 45974 | N10: H04 | O10: 7 | P10: 266 | Q10: 税理士スタンダードコース | R10: 2 | S10: 1 | T10: 税理士会計士系 | U10: 3 | V10: 2680069 | W10: 0 | Z10: V | AA10: 45989 | AB10: 26 | AC10: 80069 | AD10: 57 | AE10: 11_神戸校 | AF10: 57 | AG10: 4.神戸校 | AH10: H04 | AI10: 7 | AJ10: 266 | AL10: 28282 | AM10: 市立 | AN10: 神港橘 | AO10: 28 | AP10: 兵庫 | AQ10: 0 | AR10: Y | AT10: 現役 | AU10: R以外
A11: 2605700010 | B11: 57 | C11: 11_神戸校 | D11: 57 | E11: 4.神戸校 | F11: 藤井 陽菜 | G11: ﾌｼﾞｲ ﾋﾅ | H11: 2 | I11: 679-0221 | J11: 兵庫県 | K11: 2026 | L11: 2026 | M11: 45989 | N11: H04 | O11: 2ｱ | P11: 857 | Q11: 府庁・県庁等初級レベルコース | R11: 1 | S11: 2 | T11: 公務員 | U11: 1 | V11: 2680138 | W11: 0 | Z11: S | AA11: 46059 | AB11: 26 | AC11: 80138 | AD11: 57 | AE11: 11_神戸校 | AF11: 57 | AG11: 4.神戸校 | AH11: H04 | AI11: 2ｱ | AJ11: 857 | AL11: 28120 | AM11: 県立 | AN11: 三木東 | AO11: 28 | AP11: 兵庫 | AQ11: 0 | AR11: Y | AT11: 現役 | AU11: R以外
A12: 2605700012 | B12: 57 | C12: 11_神戸校 | D12: 57 | E12: 4.神戸校 | F12: 山本 拓実 | G12: ﾔﾏﾓﾄ ﾀｸﾐ | H12: 1 | I12: 658-0083 | J12: 兵庫県 | K12: 0 | L12: 2026 | M12: 45996 | N12: H04 | O12: BF | P12: 95 | Q12: 税理士専攻コース | R12: 1 | S12: 37 | T12: 専攻科税理士系 | U12: 28 | V12: 2680081 | W12: 0 | Z12: C | AA12: 46006 | AB12: 26 | AC12: 80081 | AD12: 57 | AE12: 11_神戸校 | AF12: 57 | AG12: 4.神戸校 | AH12: H04 | AI12: BF | AJ12: 95 | AL12: 28030 | AM12: 県立 | AN12: 神戸商業 | AO12: 28 | AP12: 兵庫 | AQ12: 0 | AR12: Y | AT12: 現役以外 | AU12: R以外
A13: 2605700013 | B13: 57 | C13: 11_神戸校 | D13: 57 | E13: 4.神戸校 | F13: 藤𠩤 翼 | G13: ﾌｼﾞﾜﾗ ﾂﾊﾞｻ | H13: 1 | I13: 651-2311 | J13: 兵庫県 | K13: 2026 | L13: 2026 | M13: 46001 | N13: H04 | O13: 2ｱ | P13: 428 | Q13: 消防官コース | R13: 1 | S13: 2 | T13: 公務員 | U13: 1 | V13: 2680141 | W13: 0 | Z13: V | AA13: 46065 | AB13: 26 | AC13: 80141 | AD13: 57 | AE13: 11_神戸校 | AF13: 57 | AG13: 4.神戸校 | AH13: H04 | AI13: 2ｱ | AJ13: 428 | AL13: 28120 | AM13: 県立 | AN13: 三木東 | AO13: 28 | AP13: 兵庫 | AQ13: 0 | AR13: Y | AT13: 現役 | AU13: R以外
A14: 2605700014 | B14: 57 | C14: 11_神戸校 | D14: 57 | E14: 4.神戸校 | F14: 神田 美宙 | G14: ｶﾝﾀﾞ ﾐﾕ | H14: 2 | I14: 655-0882 | J14: 兵庫県 | K14: 0 | L14: 2026 | M14: 46027 | N14: H04 | O14: 7 | P14: 266 | Q14: 税理士スタンダードコース | R14: 2 | S14: 1 | T14: 税理士会計士系 | U14: 3 | V14: 2680130 | W14: 0 | AA14: 46041 | AB14: 26 | AC14: 80130 | AD14: 57 | AE14: 11_神戸校 | AF14: 57 | AG14: 4.神戸校 | AH14: H04 | AI14: 7 | AJ14: 266 | AL14: 28198 | AM14: 県立 | AN14: 須磨友が丘 | AO14: 28 | AP14: 兵庫 | AQ14: 0 | AR14: Y | AT14: 現役以外 | AU14: R以外
A15: 2605700015 | B15: 57 | C15: 11_神戸校 | D15: 57 | E15: 4.神戸校 | F15: 中塚 雪乃 | G15: ﾅｶﾂｶ ﾕｷﾉ | H15: 2 | I15: 655-0892 | J15: 兵庫県 | K15: 2026 | L15: 2026 | M15: 46030 | N15: H04 | O15: 58 | P15: 290 | Q15: 公務員総合コース | R15: 2 | S15: 2 | T15: 公務員 | U15: 1 | V15: 0 | W15: 0 | AB15: 0 | AC15: 0 | AD15: 0 | AE15: 0_未手続 | AG15: 0_未手続 | AJ15: 0 | AK15: Y | AL15: 28210 | AM15: 県立 | AN15: 伊川谷北 | AO15: 28 | AP15: 兵庫 | AQ15: 0 | AR15: Y | AT15: 現役 | AU15: R以外
A16: 2605700016 | B16: 57 | C16: 11_神戸校 | D16: 57 | E16: 4.神戸校 | F16: 神吉 颯之介 | G16: ｶﾝｷ ｿｳﾉｽｹ | H16: 1 | I16: 673-0442 | J16: 兵庫県 | K16: 0 | L16: 2026 | M16: 46031 | N16: H04 | O16: 2ｱ | P16: 56 | Q16: 警察官・消防官コース | R16: 1 | S16: 36 | T16: 専攻科公務員系 | U16: 27 | V16: 2680133 | W16: 0 | Z16: C | AA16: 46049 | AB16: 26 | AC16: 80133 | AD16: 57 | AE16: 11_神戸校 | AF16: 57 | AG16: 4.神戸校 | AH16: H04 | AI16: 2ｱ | AJ16: 56 | AL16: 28033 | AM16: 県立 | AN16: 吉川 | AO16: 28 | AP16: 兵庫 | AQ16: 0 | AR16: Y | AT16: 現役以外 | AU16: R以外
A17: 2605700017 | B17: 57 | C17: 11_神戸校 | D17: 57 | E17: 4.神戸校 | F17: 川濱 圭佑 | G17: ｶﾜﾊﾏ ｹｲｽｹ | H17: 1 | I17: 667-1105 | J17: 兵庫県 | K17: 2026 | L17: 2026 | M17: 46033 | N17: H04 | O17: 0ｽ | P17: 502 | Q17: スポーツトレーナーコース | R17: 2 | S17: 5 | T17: スポーツ系 | U17: 15 | V17: 2680135 | W17: 0 | Z17: S | AA17: 46050 | AB17: 26 | AC17: 80135 | AD17: 57 | AE17: 11_神戸校 | AF17: 57 | AG17: 4.神戸校 | AH17: H04 | AI17: 0ｽ | AJ17: 502 | AL17: 28180 | AM17: 県立 | AN17: 八鹿 | AO17: 28 | AP17: 兵庫 | AQ17: 0 | AR17: Y | AT17: 現役 | AU17: R以外
A18: 2605700018 | B18: 57 | C18: 11_神戸校 | D18: 57 | E18: 4.神戸校 | F18: 小林 桜介 | G18: ｺﾊﾞﾔｼ ｵｳｽｹ | H18: 1 | I18: 625-0070 | J18: 京都府 | K18: 2026 | L18: 2026 | M18: 46037 | N18: H04 | O18: 58 | P18: 428 | Q18: 消防官コース | R18: 2 | S18: 2 | T18: 公務員 | U18: 1 | V18: 0 | W18: 0 | AB18: 0 | AC18: 0 | AD18: 0 | AE18: 0_未手続 | AG18: 0_未手続 | AJ18: 0 | AK18: Y | AL18: 26069 | AM18: 府立 | AN18: 西舞鶴 | AO18: 26 | AP18: 京都 | AQ18: 0 | AR18: Y | AT18: 現役 | AU18: R以外
A19: 2605700019 | B19: 57 | C19: 11_神戸校 | D19: 57 | E19: 4.神戸校 | F19: 川野 紗菜 | G19: ｶﾜﾉ ｻﾅ | H19: 2 | I19: 656-1344 | J19: 兵庫県 | K19: 2026 | L19: 2026 | M19: 46043 | N19: H04 | O19: 58 | P19: 857 | Q19: 府庁・県庁等初級レベルコース | R19: 2 | S19: 2 | T19: 公務員 | U19: 1 | V19: 2680136 | W19: 0 | Z19: S | AA19: 46057 | AB19: 26 | AC19: 80136 | AD19: 57 | AE19: 11_神戸校 | AF19: 57 | AG19: 4.神戸校 | AH19: H04 | AI19: 58 | AJ19: 857 | AL19: 28150 | AM19: 県立 | AN19: 洲本実業 | AO19: 28 | AP19: 兵庫 | AQ19: 0 | AR19: Y | AT19: 現役 | AU19: R以外
A20: 2605700020 | B20: 57 | C20: 11_神戸校 | D20: 57 | E20: 4.神戸校 | F20: 倉本 駿 | G20: ｸﾗﾓﾄ ｼｭﾝ | H20: 1 | I20: 651-0073 | J20: 兵庫県 | K20: 2026 | L20: 2026 | M20: 46046 | N20: H04 | O20: 58 | P20: 856 | Q20: 国家公務員初級レベルコース | R20: 2 | S20: 2 | T20: 公務員 | U20: 1 | V20: 2680140 | W20: 0 | Z20: S | AA20: 46062 | AB20: 26 | AC20: 80140 | AD20: 57 | AE20: 11_神戸校 | AF20: 57 | AG20: 4.神戸校 | AH20: H04 | AI20: 58 | AJ20: 856 | AL20: 28030 | AM20: 県立 | AN20: 神戸商業 | AO20: 28 | AP20: 兵庫 | AQ20: 0 | AR20: Y | AT20: 現役 | AU20: R以外
A21: 2605700021 | B21: 57 | C21: 11_神戸校 | D21: 57 | E21: 4.神戸校 | F21: 鍋内 真人 | G21: ﾅﾍﾞｳﾁ ﾏｻﾄ | H21: 1 | I21: 651-1332 | J21: 兵庫県 | K21: 2026 | L21: 2026 | M21: 46046 | N21: H04 | O21: 58 | P21: 428 | Q21: 消防官コース | R21: 2 | S21: 2 | T21: 公務員 | U21: 1 | V21: 2680139 | W21: 0 | AA21: 46062 | AB21: 26 | AC21: 80139 | AD21: 57 | AE21: 11_神戸校 | AF21: 57 | AG21: 4.神戸校 | AH21: H04 | AI21: 58 | AJ21: 428 | AL21: 28009 | AM21: 県立 | AN21: 神戸甲北 | AO21: 28 | AP21: 兵庫 | AQ21: 0 | AR21: Y | AT21: 現役 | AU21: R以外
A22: 2605700022 | B22: 57 | C22: 11_神戸校 | D22: 57 | E22: 4.神戸校 | F22: 髙須加 愛 | G22: ﾀｶｽｶ ｱｲ | H22: 2 | I22: 654-0132 | J22: 兵庫県 | K22: 2026 | L22: 2026 | M22: 46046 | N22: H04 | O22: 57 | P22: 1775 | Q22: オフィスビジネス専攻コース | R22: 2 | S22: 3 | T22: ビジネス系 | U22: 4 | V22: 2680143 | W22: 0 | Z22: S | AA22: 46065 | AB22: 26 | AC22: 80143 | AD22: 57 | AE22: 11_神戸校 | AF22: 57 | AG22: 4.神戸校 | AH22: H04 | AI22: 57 | AJ22: 1775 | AL22: 28282 | AM22: 市立 | AN22: 神港橘 | AO22: 28 | AP22: 兵庫 | AQ22: 0 | AR22: Y | AT22: 現役 | AU22: R以外
A23: 2605700023 | B23: 57 | C23: 11_神戸校 | D23: 57 | E23: 4.神戸校 | F23: 海老名 ひなた | G23: ｴﾋﾞﾅ ﾋﾅﾀ | H23: 2 | I23: 676-0082 | J23: 兵庫県 | K23: 0 | L23: 2026 | M23: 46048 | N23: H04 | O23: 6 | P23: 488 | Q23: 公認会計士スタンダードコース | R23: 2 | S23: 1 | T23: 税理士会計士系 | U23: 3 | V23: 0 | W23: 0 | AB23: 0 | AC23: 0 | AD23: 0 | AE23: 0_未手続 | AG23: 0_未手続 | AJ23: 0 | AL23: 28102 | AM23: 県立 | AN23: 加古川西 | AO23: 28 | AP23: 兵庫 | AQ23: 0 | AR23: Y | AT23: 現役以外 | AU23: R以外
A24: 2605700024 | B24: 57 | C24: 11_神戸校 | D24: 57 | E24: 4.神戸校 | F24: 岡田 莉奈 | G24: ｵｶﾀﾞ ﾘﾅ | H24: 2 | I24: 675-0066 | J24: 兵庫県 | K24: 2026 | L24: 2026 | M24: 46053 | N24: H04 | O24: 6 | P24: 488 | Q24: 公認会計士スタンダードコース | R24: 2 | S24: 1 | T24: 税理士会計士系 | U24: 3 | V24: 0 | W24: 0 | AB24: 0 | AC24: 0 | AD24: 0 | AE24: 0_未手続 | AG24: 0_未手続 | AJ24: 0 | AL24: 28041 | AM24: 私立 | AN24: 松蔭 | AO24: 28 | AP24: 兵庫 | AQ24: 0 | AR24: Y | AT24: 現役 | AU24: R以外
A25: 2605700025 | B25: 57 | C25: 11_神戸校 | D25: 57 | E25: 4.神戸校 | F25: 大濱 実紗 | G25: ｵｵﾊﾏ ﾐｻ | H25: 2 | I25: 656-0471 | J25: 兵庫県 | K25: 2026 | L25: 2026 | M25: 46056 | N25: H04 | O25: 7 | P25: 266 | Q25: 税理士スタンダードコース | R25: 2 | S25: 1 | T25: 税理士会計士系 | U25: 3 | V25: 0 | W25: 0 | AB25: 0 | AC25: 0 | AD25: 0 | AE25: 0_未手続 | AG25: 0_未手続 | AJ25: 0 | AL25: 28246 | AM25: 県立 | AN25: 淡路三原 | AO25: 28 | AP25: 兵庫 | AQ25: 0 | AR25: Y | AT25: 現役 | AU25: R以外
A26: 2605700801 | B26: 57 | C26: 11_神戸校 | D26: 57 | E26: 4.神戸校 | F26: レ イェン ニィ | G26: ﾚ ｲｪﾝ ﾆｨ | H26: 2 | I26: 671-0253 | J26: 兵庫県 | K26: 2026 | L26: 2026 | M26: 45901 | N26: H04 | O26: 57 | P26: 1044 | Q26: 事務・経理職専攻コース | R26: 2 | S26: 3 | T26: ビジネス系 | U26: 4 | V26: 2680034 | W26: 0 | Z26: D | AA26: 45960 | AB26: 26 | AC26: 80034 | AD26: 57 | AE26: 11_神戸校 | AF26: 57 | AG26: 4.神戸校 | AH26: H04 | AI26: 1Q | AJ26: 1170 | AL26: 50448 | AN26: 創智国際学院 | AO26: 28 | AP26: 兵庫 | AQ26: 1 | AR26: Y | AT26: 現役 | AU26: R以外
A27: 2605700802 | B27: 57 | C27: 11_神戸校 | D27: 57 | E27: 4.神戸校 | F27: シワコティ ディペス | G27: ｼﾜｺﾃｨ ﾃﾞｨﾍﾟｽ | H27: 1 | I27: 670-0844 | J27: 兵庫県 | K27: 2026 | L27: 2026 | M27: 45901 | N27: H04 | O27: 57 | P27: 1044 | Q27: 事務・経理職専攻コース | R27: 2 | S27: 3 | T27: ビジネス系 | U27: 4 | V27: 0 | W27: 0 | Z27: D | AB27: 0 | AC27: 0 | AD27: 0 | AE27: 0_未手続 | AG27: 0_未手続 | AJ27: 0 | AL27: 50448 | AN27: 創智国際学院 | AO27: 28 | AP27: 兵庫 | AQ27: 1 | AR27: N | AT27: 現役 | AU27: R以外
A28: 2605700803 | B28: 57 | C28: 11_神戸校 | D28: 57 | E28: 4.神戸校 | F28: ガハ ビバシュ | G28: ｶﾞﾊ ﾋﾞﾊﾞｼｭ | H28: 1 | I28: 658-0073 | J28: 兵庫県 | K28: 2026 | L28: 2026 | M28: 45921 | N28: H04 | O28: 1Q | P28: 1170 | Q28: 国際コミュニケーション（スタンダード） | R28: 1 | S28: 15 | T28: 留学生 | U28: 37 | V28: 2680045 | W28: 0 | Z28: D | AA28: 45974 | AB28: 26 | AC28: 80045 | AD28: 57 | AE28: 11_神戸校 | AF28: 57 | AG28: 4.神戸校 | AH28: H04 | AI28: 1Q | AJ28: 1170 | AL28: 50446 | AN28: 日本語学院みらい | AO28: 28 | AP28: 兵庫 | AQ28: 1 | AR28: Y | AT28: 現役 | AU28: R以外
A29: 2605700804 | B29: 57 | C29: 11_神戸校 | D29: 57 | E29: 4.神戸校 | F29: ズオン クアン フイ | G29: ｽﾞｵﾝ ｸｱﾝ ﾌｲ | H29: 1 | I29: 676-0827 | J29: 兵庫県 | K29: 2026 | L29: 2026 | M29: 45930 | N29: H04 | O29: 1Q | P29: 1170 | Q29: 国際コミュニケーション（スタンダード） | R29: 1 | S29: 15 | T29: 留学生 | U29: 37 | V29: 2680062 | W29: 0 | Z29: D | AA29: 45986 | AB29: 26 | AC29: 80062 | AD29: 57 | AE29: 11_神戸校 | AF29: 57 | AG29: 4.神戸校 | AH29: H04 | AI29: 1Q | AJ29: 1170 | AL29: 50740 | AN29: Ｎｅｓｔ２１日本語学院 | AO29: 28 | AP29: 兵庫 | AQ29: 1 | AR29: Y | AT29: 現役 | AU29: R以外
A30: 2605700805 | B30: 57 | C30: 11_神戸校 | D30: 57 | E30: 4.神戸校 | F30: ロカヤ ラクシュミ クマリ | G30: ﾛｶﾔ ﾗｸｼｭﾐ ｸﾏﾘ | H30: 2 | I30: 676-0827 | J30: 兵庫県 | K30: 2026 | L30: 2026 | M30: 45934 | N30: H04 | O30: 1Q | P30: 1170 | Q30: 国際コミュニケーション（スタンダード） | R30: 1 | S30: 15 | T30: 留学生 | U30: 37 | V30: 2680057 | W30: 0 | Z30: D | AA30: 45981 | AB30: 26 | AC30: 80057 | AD30: 57 | AE30: 11_神戸校 | AF30: 57 | AG30: 4.神戸校 | AH30: H04 | AI30: 1Q | AJ30: 1170 | AL30: 50740 | AN30: Ｎｅｓｔ２１日本語学院 | AO30: 28 | AP30: 兵庫 | AQ30: 1 | AR30: Y | AT30: 現役 | AU30: R以外
A31: 2605700806 | B31: 57 | C31: 11_神戸校 | D31: 57 | E31: 4.神戸校 | F31: メイ ジン トウ | G31: ﾒｲ ｼﾞﾝ ﾄｳ | H31: 2 | I31: 651-0093 | J31: 兵庫県 | K31: 2026 | L31: 2026 | M31: 45936 | N31: H04 | O31: 1Q | P31: 1170 | Q31: 国際コミュニケーション（スタンダード） | R31: 1 | S31: 15 | T31: 留学生 | U31: 37 | V31: 2680043 | W31: 0 | Z31: D | AA31: 45972 | AB31: 26 | AC31: 80043 | AD31: 57 | AE31: 11_神戸校 | AF31: 57 | AG31: 4.神戸校 | AH31: H04 | AI31: 1Q | AJ31: 1170 | AL31: 50446 | AN31: 日本語学院みらい | AO31: 28 | AP31: 兵庫 | AQ31: 1 | AR31: Y | AT31: 現役 | AU31: R以外
A32: 2605700807 | B32: 57 | C32: 11_神戸校 | D32: 57 | E32: 4.神戸校 | F32: グエン ティ キム クイ | G32: ｸﾞｴﾝ ﾃｨ ｷﾑ ｸｲ | H32: 2 | I32: 650-0017 | J32: 兵庫県 | K32: 0 | L32: 2026 | M32: 45938 | N32: H04 | O32: 57 | P32: 1756 | Q32: マーケティングビジネス専攻 | R32: 2 | S32: 3 | T32: ビジネス系 | U32: 4 | V32: 2680050 | W32: 0 | Z32: D | AA32: 45979 | AB32: 26 | AC32: 80050 | AD32: 57 | AE32: 11_神戸校 | AF32: 57 | AG32: 4.神戸校 | AH32: H04 | AI32: 57 | AJ32: 1756 | AL32: 50811 | AN32: 五島日本語学校 | AO32: 42 | AP32: 長崎 | AQ32: 1 | AR32: Y | AT32: 現役以外 | AU32: R以外
A33: 2605700808 | B33: 57 | C33: 11_神戸校 | D33: 57 | E33: 4.神戸校 | F33: ホサン アズマイン | G33: ﾎｻﾝ ｱｽﾞﾏｲﾝ | H33: 1 | I33: 650-0003 | J33: 兵庫県 | K33: 2026 | L33: 2026 | M33: 45940 | N33: H04 | O33: 1Q | P33: 1170 | Q33: 国際コミュニケーション（スタンダード） | R33: 1 | S33: 15 | T33: 留学生 | U33: 37 | V33: 2680066 | W33: 0 | Z33: D | AA33: 45988 | AB33: 26 | AC33: 80066 | AD33: 57 | AE33: 11_神戸校 | AF33: 57 | AG33: 4.神戸校 | AH33: H04 | AI33: 1Q | AJ33: 1170 | AL33: 50446 | AN33: 日本語学院みらい | AO33: 28 | AP33: 兵庫 | AQ33: 1 | AR33: Y | AT33: 現役 | AU33: R以外
A34: 2605700809 | B34: 57 | C34: 11_神戸校 | D34: 57 | E34: 4.神戸校 | F34: ミム シャキラ アクタル | G34: ﾐﾑ ｼｬｷﾗ ｱｸﾀﾙ | H34: 2 | I34: 650-0012 | J34: 兵庫県 | K34: 2026 | L34: 2026 | M34: 45940 | N34: H04 | O34: 1Q | P34: 1170 | Q34: 国際コミュニケーション（スタンダード） | R34: 1 | S34: 15 | T34: 留学生 | U34: 37 | V34: 2680068 | W34: 0 | Z34: D | AA34: 45989 | AB34: 26 | AC34: 80068 | AD34: 57 | AE34: 11_神戸校 | AF34: 57 | AG34: 4.神戸校 | AH34: H04 | AI34: 1Q | AJ34: 1170 | AL34: 50446 | AN34: 日本語学院みらい | AO34: 28 | AP34: 兵庫 | AQ34: 1 | AR34: Y | AT34: 現役 | AU34: R以外
A35: 2605700810 | B35: 57 | C35: 11_神戸校 | D35: 57 | E35: 4.神戸校 | F35: イスラム エムディ トリクル | G35: ｲｽﾗﾑ ｴﾑﾃﾞｨ ﾄﾘｸﾙ | H35: 1 | I35: 661-0981 | J35: 兵庫県 | K35: 2026 | L35: 2026 | M35: 45940 | N35: H04 | O35: 57 | P35: 1756 | Q35: マーケティングビジネス専攻 | R35: 2 | S35: 3 | T35: ビジネス系 | U35: 4 | V35: 2680086 | W35: 0 | Z35: D | AA35: 46007 | AB35: 26 | AC35: 80086 | AD35: 57 | AE35: 11_神戸校 | AF35: 57 | AG35: 4.神戸校 | AH35: H04 | AI35: 1Q | AJ35: 1170 | AL35: 50726 | AN35: 大阪観光大学日本語別科伊丹サテライト校 | AO35: 28 | AP35: 兵庫 | AQ35: 1 | AR35: Y | AT35: 現役 | AU35: R以外
A36: 2605700811 | B36: 57 | C36: 11_神戸校 | D36: 57 | E36: 4.神戸校 | F36: フィン ヴァン クオン | G36: ﾌｨﾝ ｳﾞｧﾝ ｸｵﾝ | H36: 1 | I36: 671-0232 | J36: 兵庫県 | K36: 2026 | L36: 2026 | M36: 45942 | N36: H04 | O36: 1Q | P36: 1170 | Q36: 国際コミュニケーション（スタンダード） | R36: 1 | S36: 15 | T36: 留学生 | U36: 37 | V36: 2680067 | W36: 0 | Z36: D | AA36: 45988 | AB36: 26 | AC36: 80067 | AD36: 57 | AE36: 11_神戸校 | AF36: 57 | AG36: 4.神戸校 | AH36: H04 | AI36: 1Q | AJ36: 1170 | AL36: 50740 | AN36: Ｎｅｓｔ２１日本語学院 | AO36: 28 | AP36: 兵庫 | AQ36: 1 | AR36: Y | AT36: 現役 | AU36: R以外
A37: 2605700812 | B37: 57 | C37: 11_神戸校 | D37: 57 | E37: 4.神戸校 | F37: チャン トゥイ ティエン | G37: ﾁｬﾝ ﾄｩｲ ﾃｨｴﾝ | H37: 2 | I37: 124-0002 | J37: 東京都 | K37: 2026 | L37: 2026 | M37: 45948 | N37: H04 | O37: 1Q | P37: 1170 | Q37: 国際コミュニケーション（スタンダード） | R37: 1 | S37: 15 | T37: 留学生 | U37: 37 | V37: 0 | W37: 0 | Z37: D | AB37: 0 | AC37: 0 | AD37: 0 | AE37: 0_未手続 | AG37: 0_未手続 | AJ37: 0 | AL37: 50058 | AN37: 城東日本語学校 | AO37: 13 | AP37: 東京 | AQ37: 1 | AR37: Y | AT37: 現役 | AU37: R以外
A38: 2605700813 | B38: 57 | C38: 11_神戸校 | D38: 57 | E38: 4.神戸校 | F38: サン トゥン アウン | G38: ｻﾝ ﾄｩﾝ ｱｳﾝ | H38: 1 | I38: 650-0011 | J38: 兵庫県 | K38: 2026 | L38: 2026 | M38: 45953 | N38: H04 | O38: 1Q | P38: 1170 | Q38: 国際コミュニケーション（スタンダード） | R38: 1 | S38: 15 | T38: 留学生 | U38: 37 | V38: 2680071 | W38: 0 | Z38: D | AA38: 45994 | AB38: 26 | AC38: 80071 | AD38: 57 | AE38: 11_神戸校 | AF38: 57 | AG38: 4.神戸校 | AH38: H04 | AI38: 1Q | AJ38: 1170 | AL38: 50339 | AN38: 神戸東洋日本語学院 | AO38: 28 | AP38: 兵庫 | AQ38: 1 | AR38: Y | AT38: 現役 | AU38: R以外
A39: 2605700814 | B39: 57 | C39: 11_神戸校 | D39: 57 | E39: 4.神戸校 | F39: ワルナクラスーリヤ ドゥラカラ サスミタ | G39: ﾜﾙﾅｸﾗｽｰﾘﾔ ﾄﾞｩﾗｶﾗ ｻｽﾐﾀ | H39: 1 | I39: 658-0044 | J39: 兵庫県 | K39: 2026 | L39: 2026 | M39: 45953 | N39: H04 | O39: 1Q | P39: 1170 | Q39: 国際コミュニケーション（スタンダード） | R39: 1 | S39: 15 | T39: 留学生 | U39: 37 | V39: 2680085 | W39: 0 | Z39: D | AA39: 46007 | AB39: 26 | AC39: 80085 | AD39: 57 | AE39: 11_神戸校 | AF39: 57 | AG39: 4.神戸校 | AH39: H04 | AI39: 1Q | AJ39: 1170 | AL39: 50735 | AN39: 神戸ＫＲ学院 | AO39: 28 | AP39: 兵庫 | AQ39: 1 | AR39: Y | AT39: 現役 | AU39: R以外
A40: 2605700815 | B40: 57 | C40: 11_神戸校 | D40: 57 | E40: 4.神戸校 | F40: タパ クリサ | G40: ﾀﾊﾟ ｸﾘｻ | H40: 2 | I40: 577-0015 | J40: 大阪府 | K40: 2026 | L40: 2026 | M40: 45953 | N40: H04 | O40: 57 | P40: 1775 | Q40: オフィスビジネス専攻コース | R40: 2 | S40: 3 | T40: ビジネス系 | U40: 4 | V40: 0 | W40: 0 | Z40: D | AB40: 0 | AC40: 0 | AD40: 0 | AE40: 0_未手続 | AG40: 0_未手続 | AJ40: 0 | AL40: 50749 | AN40: 大阪ニューポイント日本語学校 | AO40: 27 | AP40: 大阪 | AQ40: 1 | AR40: N | AT40: 現役 | AU40: R以外
...

Sheet 2027年度出願
A1: kanrino | B1: obscd | C1: obsname | D1: obscd2 | E1: obsname2 | F1: name | G1: namekana | H1: sex | I1: yubin | J1: adres1 | K1: kousdt | L1: nendo | M1: juridt | N1: sktikbn | O1: skatei | P1: scourse | Q1: コース名 | R1: syugyonen | S1: コース系列コード | T1: コース系列名 | U1: 並び順 | V1: kihonno | W1: utiwake | X1: utiwakename | Y1: jitaidt | Z1: suisencd | AA1: kanryodt | AB1: nnendo | AC1: gakuno | AD1: nobscd | AE1: nobsname | AF1: nobscd2 | AG1: nobsname2 | AH1: nktikbn | AI1: nkatei | AJ1: ncourse | AK1: heiganflg | AL1: koucd | AM1: keiei | AN1: kouname | AO1: kencode | AP1: kenname | AQ1: 留学生 | AR1: 書類合否 | AS1: 選考合否 | AT1: kousdt2 | AU1: suisencd2
A2: 2713150128 | B2: 57 | C2: 11_神戸校 | D2: 57 | E2: 4.神戸校 | F2: 小西 統 | G2: ｺﾆｼ ﾚｲﾝ | H2: 1 | I2: 655-0003 | J2: 兵庫県 | K2: 0 | L2: 2027 | M2: 46302 | N2: H04 | O2: 0ｽ | P2: 502 | Q2: スポーツトレーナーコース | R2: 2 | S2: 5 | T2: スポーツ系 | U2: 15 | V2: 0 | W2: 0 | Z2: O | AB2: 0 | AC2: 0 | AD2: 0 | AE2: 0_未手続 | AG2: 0_未手続 | AJ2: 0 | AL2: 28124 | AM2: 市立 | AN2: 明石商業 | AO2: 28 | AP2: 兵庫 | AQ2: 0 | AR2: Y | AT2: 現役以外 | AU2: R以外
A3: 2705700002 | B3: 57 | C3: 11_神戸校 | D3: 57 | E3: 4.神戸校 | F3: 鈴木 好乃 | G3: ｽｽﾞｷ ﾖｼﾉ | H3: 2 | I3: 182-0024 | J3: 東京都 | K3: 0 | L3: 2027 | M3: 46304 | N3: H04 | O3: 6 | P3: 488 | Q3: 公認会計士スタンダードコース | R3: 2 | S3: 1 | T3: 税理士会計士系 | U3: 3 | V3: 0 | W3: 0 | Z3: P | AB3: 0 | AC3: 0 | AD3: 0 | AE3: 0_未手続 | AG3: 0_未手続 | AJ3: 0 | AL3: 19010 | AM3: 私立 | AN3: 甲斐清和 | AO3: 19 | AP3: 山梨 | AQ3: 0 | AR3: Y | AT3: 現役以外 | AU3: R以外
A4: 2705700004 | B4: 57 | C4: 11_神戸校 | D4: 57 | E4: 4.神戸校 | F4: 松山 実結 | G4: ﾏﾂﾔﾏ ﾐﾕ | H4: 2 | I4: 891-9301 | J4: 鹿児島県 | K4: 2027 | L4: 2027 | M4: 46310 | N4: H04 | O4: 7 | P4: 266 | Q4: 税理士スタンダードコース | R4: 2 | S4: 1 | T4: 税理士会計士系 | U4: 3 | V4: 0 | W4: 0 | AB4: 0 | AC4: 0 | AD4: 0 | AE4: 0_未手続 | AG4: 0_未手続 | AJ4: 0 | AL4: 23253 | AM4: 私立 | AN4: ルネサンス豊田 | AO4: 23 | AP4: 愛知 | AQ4: 0 | AR4: Y | AT4: 現役 | AU4: R以外
A5: 2705700005 | B5: 57 | C5: 11_神戸校 | D5: 57 | E5: 4.神戸校 | F5: 横山 彪桜 | G5: ﾖｺﾔﾏ ﾋｵｳ | H5: 1 | I5: 655-0016 | J5: 兵庫県 | K5: 2027 | L5: 2027 | M5: 46316 | N5: H04 | O5: 58 | P5: 260 | Q5: 公務員＆民間就職コース | R5: 2 | S5: 2 | T5: 公務員 | U5: 1 | V5: 0 | W5: 0 | Z5: P | AB5: 0 | AC5: 0 | AD5: 0 | AE5: 0_未手続 | AG5: 0_未手続 | AJ5: 0 | AL5: 28030 | AM5: 県立 | AN5: 神戸商業 | AO5: 28 | AP5: 兵庫 | AQ5: 0 | AR5: Y | AT5: 現役 | AU5: R以外
A6: 2705700006 | B6: 57 | C6: 11_神戸校 | D6: 57 | E6: 4.神戸校 | F6: 荻野 塁 | G6: ｵｷﾞﾉ ﾙｲ | H6: 1 | I6: 669-3163 | J6: 兵庫県 | K6: 2027 | L6: 2027 | M6: 46319 | N6: H04 | O6: 2ｱ | P6: 428 | Q6: 消防官コース | R6: 1 | S6: 2 | T6: 公務員 | U6: 1 | V6: 0 | W6: 0 | Z6: G | AB6: 0 | AC6: 0 | AD6: 0 | AE6: 0_未手続 | AG6: 0_未手続 | AJ6: 0 | AL6: 28141 | AM6: 県立 | AN6: 西脇工業 | AO6: 28 | AP6: 兵庫 | AQ6: 0 | AT6: 現役 | AU6: R以外
A7: 2705700007 | B7: 57 | C7: 11_神戸校 | D7: 57 | E7: 4.神戸校 | F7: 前山 大輝 | G7: ﾏｴﾔﾏ ﾀﾞｲｷ | H7: 1 | I7: 673-0033 | J7: 兵庫県 | K7: 2027 | L7: 2027 | M7: 46319 | N7: H04 | O7: 0ｽ | P7: 502 | Q7: スポーツトレーナーコース | R7: 2 | S7: 5 | T7: スポーツ系 | U7: 15 | V7: 0 | W7: 0 | Z7: G | AB7: 0 | AC7: 0 | AD7: 0 | AE7: 0_未手続 | AG7: 0_未手続 | AJ7: 0 | AL7: 28152 | AM7: 県立 | AN7: 淡路 | AO7: 28 | AP7: 兵庫 | AQ7: 0 | AT7: 現役 | AU7: R以外
A8: 2705700802 | B8: 57 | C8: 11_神戸校 | D8: 57 | E8: 4.神戸校 | F8: 商 磊 | G8: ｼｮｳ ﾗｲ | H8: 1 | I8: 662-0922 | J8: 兵庫県 | K8: 2027 | L8: 2027 | M8: 46274 | N8: H04 | O8: 57 | P8: 1044 | Q8: 事務・経理職専攻コース | R8: 2 | S8: 3 | T8: ビジネス系 | U8: 4 | V8: 2780019 | W8: 0 | Z8: D | AA8: 46310 | AB8: 27 | AC8: 80019 | AD8: 57 | AE8: 11_神戸校 | AF8: 57 | AG8: 4.神戸校 | AH8: H04 | AI8: 1Q | AJ8: 1170 | AL8: 50450 | AN8: 神戸国際語言学院 | AO8: 28 | AP8: 兵庫 | AQ8: 1 | AR8: Y | AT8: 現役 | AU8: R以外
A9: 2705700804 | B9: 57 | C9: 11_神戸校 | D9: 57 | E9: 4.神戸校 | F9: ＷＡＩ ＺＩＮ ＯＯ | G9: ﾜｪｲ ｼﾞﾝ ｳｰ | H9: 2 | I9: 510-0092 | J9: 三重県 | K9: 2027 | L9: 2027 | M9: 46289 | N9: H04 | O9: 57 | P9: 1756 | Q9: マーケティングビジネス専攻 | R9: 2 | S9: 3 | T9: ビジネス系 | U9: 4 | V9: 0 | W9: 0 | Z9: D | AB9: 0 | AC9: 0 | AD9: 0 | AE9: 0_未手続 | AG9: 0_未手続 | AJ9: 0 | AL9: 0 | AO9: 0 | AQ9: 1 | AR9: N | AT9: 現役 | AU9: R以外
A10: 2705700817 | B10: 57 | C10: 11_神戸校 | D10: 57 | E10: 4.神戸校 | F10: SWE ZIN NYEIN AYE | G10: ｼｭｴ ｼﾞﾝ ﾆｪｲﾝ ｴｲ | H10: 2 | I10: 652-0837 | J10: 兵庫県 | K10: 2027 | L10: 2027 | M10: 46311 | N10: H04 | O10: 57 | P10: 1756 | Q10: マーケティングビジネス専攻 | R10: 2 | S10: 3 | T10: ビジネス系 | U10: 4 | V10: 0 | W10: 0 | Z10: D | AB10: 0 | AC10: 0 | AD10: 0 | AE10: 0_未手続 | AG10: 0_未手続 | AJ10: 0 | AL10: 50339 | AN10: 神戸東洋日本語学院 | AO10: 28 | AP10: 兵庫 | AQ10: 1 | AT10: 現役 | AU10: R以外
A11: 2705700818 | B11: 57 | C11: 11_神戸校 | D11: 57 | E11: 4.神戸校 | F11: NGO THI XUAN THU | G11: ｺﾞ ﾃｨ ｽｱﾝ ﾄｳ | H11: 2 | I11: 658-0083 | J11: 兵庫県 | K11: 0 | L11: 2027 | M11: 46315 | N11: H04 | O11: 57 | P11: 1044 | Q11: 事務・経理職専攻コース | R11: 2 | S11: 3 | T11: ビジネス系 | U11: 4 | V11: 0 | W11: 0 | Z11: D | AB11: 0 | AC11: 0 | AD11: 0 | AE11: 0_未手続 | AG11: 0_未手続 | AJ11: 0 | AL11: 50429 | AN11: 神戸住吉国際日本語学校 | AO11: 28 | AP11: 兵庫 | AQ11: 4 | AT11: 現役以外 | AU11: R以外
A12: 2705750001 | B12: 57 | C12: 11_神戸校 | D12: 57 | E12: 4.神戸校 | F12: 佐々木 さくら | G12: ｻｻｷ ｻｸﾗ | H12: 2 | I12: 675-1309 | J12: 兵庫県 | K12: 2027 | L12: 2027 | M12: 46270 | N12: H04 | O12: 58 | P12: 856 | Q12: 国家公務員初級レベルコース | R12: 2 | S12: 2 | T12: 公務員 | U12: 1 | V12: 2780004 | W12: 0 | Z12: O | AA12: 46307 | AB12: 27 | AC12: 80004 | AD12: 57 | AE12: 11_神戸校 | AF12: 57 | AG12: 4.神戸校 | AH12: H04 | AI12: 58 | AJ12: 856 | AL12: 28197 | AM12: 私立 | AN12: 神戸弘陵学園 | AO12: 28 | AP12: 兵庫 | AQ12: 0 | AR12: Y | AT12: 現役 | AU12: R以外
A13: 2705750002 | B13: 57 | C13: 11_神戸校 | D13: 57 | E13: 4.神戸校 | F13: 野村 奈未 | G13: ﾉﾑﾗ ﾅﾐ | H13: 2 | I13: 670-0061 | J13: 兵庫県 | K13: 2027 | L13: 2027 | M13: 46273 | N13: H04 | O13: 7 | P13: 266 | Q13: 税理士スタンダードコース | R13: 2 | S13: 1 | T13: 税理士会計士系 | U13: 3 | V13: 0 | W13: 0 | Z13: O | AB13: 0 | AC13: 0 | AD13: 0 | AE13: 0_未手続 | AG13: 0_未手続 | AJ13: 0 | AL13: 28247 | AM13: 県立 | AN13: 龍野北 | AO13: 28 | AP13: 兵庫 | AQ13: 0 | AR13: Y | AT13: 現役 | AU13: R以外
A14: 2705750003 | B14: 57 | C14: 11_神戸校 | D14: 57 | E14: 4.神戸校 | F14: 白山 由和 | G14: ｼﾗﾔﾏ ﾕｳﾜ | H14: 1 | I14: 655-0006 | J14: 兵庫県 | K14: 2027 | L14: 2027 | M14: 46266 | N14: H04 | O14: 0ｽ | P14: 502 | Q14: スポーツトレーナーコース | R14: 2 | S14: 5 | T14: スポーツ系 | U14: 15 | V14: 2780033 | W14: 0 | Z14: O | AA14: 46316 | AB14: 27 | AC14: 80033 | AD14: 57 | AE14: 11_神戸校 | AF14: 57 | AG14: 4.神戸校 | AH14: H04 | AI14: 0ｽ | AJ14: 502 | AL14: 28024 | AM14: 私立 | AN14: 神港学園 | AO14: 28 | AP14: 兵庫 | AQ14: 0 | AR14: Y | AT14: 現役 | AU14: R以外
A15: 2705750004 | B15: 57 | C15: 11_神戸校 | D15: 57 | E15: 4.神戸校 | F15: 田中 梨玖斗 | G15: ﾀﾅｶ ﾘｸﾄ | H15: 1 | I15: 679-2204 | J15: 兵庫県 | K15: 2027 | L15: 2027 | M15: 46266 | N15: H04 | O15: 58 | P15: 968 | Q15: 市役所・町役場等初級レベル | R15: 2 | S15: 2 | T15: 公務員 | U15: 1 | V15: 0 | W15: 0 | Z15: O | AB15: 0 | AC15: 0 | AD15: 0 | AE15: 0_未手続 | AG15: 0_未手続 | AJ15: 0 | AL15: 28223 | AM15: 私立 | AN15: クラーク記念国際芦屋キャンパス | AO15: 28 | AP15: 兵庫 | AQ15: 0 | AR15: Y | AT15: 現役 | AU15: R以外
A16: 2705750005 | B16: 57 | C16: 11_神戸校 | D16: 57 | E16: 4.神戸校 | F16: 藤原 朱雀 | G16: ﾌｼﾞﾜﾗ ｽｻﾞｸ | H16: 1 | I16: 676-0082 | J16: 兵庫県 | K16: 2027 | L16: 2027 | M16: 46321 | N16: H04 | O16: 58 | P16: 428 | Q16: 消防官コース | R16: 2 | S16: 2 | T16: 公務員 | U16: 1 | V16: 0 | W16: 0 | Z16: O | AB16: 0 | AC16: 0 | AD16: 0 | AE16: 0_未手続 | AG16: 0_未手続 | AJ16: 0 | AL16: 28103 | AM16: 県立 | AN16: 高砂 | AO16: 28 | AP16: 兵庫 | AQ16: 0 | AT16: 現役 | AU16: R以外
A17: 2705750006 | B17: 57 | C17: 11_神戸校 | D17: 57 | E17: 4.神戸校 | F17: 近藤 拓友 | G17: ｺﾝﾄﾞｳ ﾀｸﾄ | H17: 1 | I17: 654-0103 | J17: 兵庫県 | K17: 2027 | L17: 2027 | M17: 46291 | N17: H04 | O17: 0ｽ | P17: 628 | Q17: フィットネストレーナーコース | R17: 2 | S17: 5 | T17: スポーツ系 | U17: 15 | V17: 0 | W17: 0 | Z17: O | AB17: 0 | AC17: 0 | AD17: 0 | AE17: 0_未手続 | AG17: 0_未手続 | AJ17: 0 | AL17: 28197 | AM17: 私立 | AN17: 神戸弘陵学園 | AO17: 28 | AP17: 兵庫 | AQ17: 0 | AR17: Y | AT17: 現役 | AU17: R以外
A18: 2705750007 | B18: 57 | C18: 11_神戸校 | D18: 57 | E18: 4.神戸校 | F18: 吉元 航汰 | G18: ﾖｼﾓﾄ ｺｳﾀ | H18: 1 | I18: 651-2117 | J18: 兵庫県 | K18: 2027 | L18: 2027 | M18: 46271 | N18: H04 | O18: 58 | P18: 428 | Q18: 消防官コース | R18: 2 | S18: 2 | T18: 公務員 | U18: 1 | V18: 0 | W18: 0 | Z18: O | AB18: 0 | AC18: 0 | AD18: 0 | AE18: 0_未手続 | AG18: 0_未手続 | AJ18: 0 | AL18: 28032 | AM18: 私立 | AN18: 神戸星城 | AO18: 28 | AP18: 兵庫 | AQ18: 0 | AR18: Y | AT18: 現役 | AU18: R以外
A19: 2705750008 | B19: 57 | C19: 11_神戸校 | D19: 57 | E19: 4.神戸校 | F19: 小嶋 凛 | G19: ｺｼﾞﾏ ﾘﾝ | H19: 2 | I19: 671-1204 | J19: 兵庫県 | K19: 2027 | L19: 2027 | M19: 46279 | N19: H04 | O19: 0ｼ | P19: 121 | Q19: 医療事務コース | R19: 2 | S19: 8 | T19: 医療事務系 | U19: 6 | V19: 0 | W19: 0 | Z19: O | AB19: 0 | AC19: 0 | AD19: 0 | AE19: 0_未手続 | AG19: 0_未手続 | AJ19: 0 | AL19: 28098 | AM19: 県立 | AN19: 姫路商業 | AO19: 28 | AP19: 兵庫 | AQ19: 0 | AR19: Y | AT19: 現役 | AU19: R以外
A20: 2705750009 | B20: 57 | C20: 11_神戸校 | D20: 57 | E20: 4.神戸校 | F20: 加田 晄 | G20: ｶﾀﾞ ｱｷﾗ | H20: 1 | I20: 663-8153 | J20: 兵庫県 | K20: 0 | L20: 2027 | M20: 46299 | N20: H04 | O20: 6 | P20: 488 | Q20: 公認会計士スタンダードコース | R20: 2 | S20: 1 | T20: 税理士会計士系 | U20: 3 | V20: 2780037 | W20: 0 | Z20: O | AA20: 46317 | AB20: 27 | AC20: 80037 | AD20: 57 | AE20: 11_神戸校 | AF20: 57 | AG20: 4.神戸校 | AH20: H04 | AI20: 6 | AJ20: 488 | AL20: 28063 | AM20: 県立 | AN20: 鳴尾 | AO20: 28 | AP20: 兵庫 | AQ20: 0 | AR20: Y | AT20: 現役以外 | AU20: R以外
A21: 2705750010 | B21: 57 | C21: 11_神戸校 | D21: 57 | E21: 4.神戸校 | F21: 藤原 冴那 | G21: ﾌｼﾞﾜﾗ ｻﾅ | H21: 2 | I21: 675-0051 | J21: 兵庫県 | K21: 2027 | L21: 2027 | M21: 46280 | N21: H04 | O21: 7 | P21: 266 | Q21: 税理士スタンダードコース | R21: 2 | S21: 1 | T21: 税理士会計士系 | U21: 3 | V21: 2780015 | W21: 0 | Z21: O | AA21: 46309 | AB21: 27 | AC21: 80015 | AD21: 57 | AE21: 11_神戸校 | AF21: 57 | AG21: 4.神戸校 | AH21: H04 | AI21: 7 | AJ21: 266 | AL21: 28277 | AM21: 私立 | AN21: Ｆ．Ｓ．播磨西高等学院 | AO21: 28 | AP21: 兵庫 | AQ21: 0 | AR21: Y | AT21: 現役 | AU21: R以外
A22: 2705750011 | B22: 57 | C22: 11_神戸校 | D22: 57 | E22: 4.神戸校 | F22: 安在 七海 | G22: ｱﾝｻﾞｲ ﾅﾅﾐ | H22: 2 | I22: 671-2544 | J22: 兵庫県 | K22: 2027 | L22: 2027 | M22: 46300 | N22: H04 | O22: 0ｼ | P22: 490 | Q22: 小児クラークコース | R22: 2 | S22: 8 | T22: 医療事務系 | U22: 6 | V22: 0 | W22: 0 | Z22: O | AB22: 0 | AC22: 0 | AD22: 0 | AE22: 0_未手続 | AG22: 0_未手続 | AJ22: 0 | AL22: 28168 | AM22: 県立 | AN22: 山崎 | AO22: 28 | AP22: 兵庫 | AQ22: 0 | AR22: Y | AT22: 現役 | AU22: R以外
A23: 2705750012 | B23: 57 | C23: 11_神戸校 | D23: 57 | E23: 4.神戸校 | F23: 藤吉 透陽 | G23: ﾌｼﾞﾖｼ ﾄｳﾔ | H23: 1 | I23: 651-2113 | J23: 兵庫県 | K23: 2027 | L23: 2027 | M23: 46299 | N23: H04 | O23: 57 | P23: 645 | Q23: 独立経営専攻コース | R23: 2 | S23: 3 | T23: ビジネス系 | U23: 4 | V23: 2780039 | W23: 0 | Z23: O | AA23: 46322 | AB23: 27 | AC23: 80039 | AD23: 57 | AE23: 11_神戸校 | AF23: 57 | AG23: 4.神戸校 | AH23: H04 | AI23: 57 | AJ23: 645 | AL23: 28121 | AM23: 県立 | AN23: 伊川谷 | AO23: 28 | AP23: 兵庫 | AQ23: 0 | AR23: Y | AT23: 現役 | AU23: R以外
A24: 2705750013 | B24: 57 | C24: 11_神戸校 | D24: 57 | E24: 4.神戸校 | F24: 松本 彩空 | G24: ﾏﾂﾓﾄ ｻﾗ | H24: 2 | I24: 673-0891 | J24: 兵庫県 | K24: 2027 | L24: 2027 | M24: 46271 | N24: H04 | O24: 57 | P24: 1756 | Q24: マーケティングビジネス専攻 | R24: 2 | S24: 3 | T24: ビジネス系 | U24: 4 | V24: 2780006 | W24: 0 | Z24: O | AA24: 46307 | AB24: 27 | AC24: 80006 | AD24: 57 | AE24: 11_神戸校 | AF24: 57 | AG24: 4.神戸校 | AH24: H04 | AI24: 57 | AJ24: 1756 | AL24: 28203 | AM24: 県立 | AN24: 神戸高塚 | AO24: 28 | AP24: 兵庫 | AQ24: 0 | AR24: Y | AT24: 現役 | AU24: R以外
A25: 2705750015 | B25: 57 | C25: 11_神戸校 | D25: 57 | E25: 4.神戸校 | F25: 呼子 杷永 | G25: ﾖﾌﾞｺ ﾊﾅﾉ | H25: 2 | I25: 654-0024 | J25: 兵庫県 | K25: 2027 | L25: 2027 | M25: 46280 | N25: H04 | O25: 58 | P25: 968 | Q25: 市役所・町役場等初級レベル | R25: 2 | S25: 2 | T25: 公務員 | U25: 1 | V25: 2780010 | W25: 0 | Z25: O | AA25: 46307 | AB25: 27 | AC25: 80010 | AD25: 57 | AE25: 11_神戸校 | AF25: 57 | AG25: 4.神戸校 | AH25: H04 | AI25: 58 | AJ25: 968 | AL25: 28261 | AM25: 市立 | AN25: 須磨翔風（単位制） | AO25: 28 | AP25: 兵庫 | AQ25: 0 | AR25: Y | AT25: 現役 | AU25: R以外
A26: 2705750016 | B26: 57 | C26: 11_神戸校 | D26: 57 | E26: 4.神戸校 | F26: 谷間 愛菜 | G26: ﾀﾆﾏ ｱﾕﾅ | H26: 2 | I26: 656-0511 | J26: 兵庫県 | K26: 2027 | L26: 2027 | M26: 46294 | N26: H04 | O26: 7 | P26: 266 | Q26: 税理士スタンダードコース | R26: 2 | S26: 1 | T26: 税理士会計士系 | U26: 3 | V26: 0 | W26: 0 | Z26: O | AB26: 0 | AC26: 0 | AD26: 0 | AE26: 0_未手続 | AG26: 0_未手続 | AJ26: 0 | AL26: 28296 | AM26: 私立 | AN26: 飛鳥未来きずな高等学校神戸キャンパス | AO26: 28 | AP26: 兵庫 | AQ26: 0 | AR26: Y | AT26: 現役 | AU26: R以外
A27: 2705750017 | B27: 57 | C27: 11_神戸校 | D27: 57 | E27: 4.神戸校 | F27: 隅野 汰良 | G27: ｽﾐﾉ ﾀｲﾗ | H27: 1 | I27: 654-0045 | J27: 兵庫県 | K27: 2027 | L27: 2027 | M27: 46315 | N27: H04 | O27: 0ｽ | P27: 1786 | Q27: スポーツ＆公務員コース | R27: 2 | S27: 5 | T27: スポーツ系 | U27: 15 | V27: 0 | W27: 0 | Z27: O | AB27: 0 | AC27: 0 | AD27: 0 | AE27: 0_未手続 | AG27: 0_未手続 | AJ27: 0 | AL27: 28121 | AM27: 県立 | AN27: 伊川谷 | AO27: 28 | AP27: 兵庫 | AQ27: 0 | AR27: Y | AT27: 現役 | AU27: R以外
A28: 2705750018 | B28: 57 | C28: 11_神戸校 | D28: 57 | E28: 4.神戸校 | F28: 佐藤 杏菜 | G28: ｻﾄｳ ｱﾝﾅ | H28: 2 | I28: 671-1643 | J28: 兵庫県 | K28: 2027 | L28: 2027 | M28: 46321 | N28: H04 | O28: 57 | P28: 1756 | Q28: マーケティングビジネス専攻 | R28: 2 | S28: 3 | T28: ビジネス系 | U28: 4 | V28: 0 | W28: 0 | Z28: O | AB28: 0 | AC28: 0 | AD28: 0 | AE28: 0_未手続 | AG28: 0_未手続 | AJ28: 0 | AL28: 28173 | AM28: 県立 | AN28: 赤穂 | AO28: 28 | AP28: 兵庫 | AQ28: 0 | AT28: 現役 | AU28: R以外
A29: 2705750019 | B29: 57 | C29: 11_神戸校 | D29: 57 | E29: 4.神戸校 | F29: 本多 志帆 | G29: ﾎﾝﾀﾞ ｼﾎ | H29: 2 | I29: 651-2401 | J29: 兵庫県 | K29: 2027 | L29: 2027 | M29: 46268 | N29: H04 | O29: 6 | P29: 488 | Q29: 公認会計士スタンダードコース | R29: 2 | S29: 1 | T29: 税理士会計士系 | U29: 3 | V29: 2780001 | W29: 0 | Z29: O | AA29: 46307 | AB29: 27 | AC29: 80001 | AD29: 57 | AE29: 11_神戸校 | AF29: 57 | AG29: 4.神戸校 | AH29: H04 | AI29: 6 | AJ29: 488 | AL29: 28108 | AM29: 県立 | AN29: 農業 | AO29: 28 | AP29: 兵庫 | AQ29: 0 | AR29: Y | AT29: 現役 | AU29: R以外
A30: 2705750020 | B30: 57 | C30: 11_神戸校 | D30: 57 | E30: 4.神戸校 | F30: 山田 和士 | G30: ﾔﾏﾀﾞ ｶｽﾞｼ | H30: 1 | I30: 655-0011 | J30: 兵庫県 | K30: 2027 | L30: 2027 | M30: 46298 | N30: H04 | O30: 58 | P30: 428 | Q30: 消防官コース | R30: 2 | S30: 2 | T30: 公務員 | U30: 1 | V30: 0 | W30: 0 | Z30: O | AB30: 0 | AC30: 0 | AD30: 0 | AE30: 0_未手続 | AG30: 0_未手続 | AJ30: 0 | AL30: 28220 | AM30: 私立 | AN30: 神戸国際 | AO30: 28 | AP30: 兵庫 | AQ30: 0 | AR30: Y | AT30: 現役 | AU30: R以外
A31: 2705750022 | B31: 57 | C31: 11_神戸校 | D31: 57 | E31: 4.神戸校 | F31: 今井 美来 | G31: ｲﾏｲ ﾁｭﾗ | H31: 2 | I31: 652-0898 | J31: 兵庫県 | K31: 2027 | L31: 2027 | M31: 46271 | N31: H04 | O31: 0ｼ | P31: 1006 | Q31: 医療事務・ビジネスコース | R31: 2 | S31: 8 | T31: 医療事務系 | U31: 6 | V31: 0 | W31: 0 | Z31: O | AB31: 0 | AC31: 0 | AD31: 0 | AE31: 0_未手続 | AG31: 0_未手続 | AJ31: 0 | AL31: 28032 | AM31: 私立 | AN31: 神戸星城 | AO31: 28 | AP31: 兵庫 | AQ31: 0 | AR31: Y | AT31: 現役 | AU31: R以外
A32: 2705750023 | B32: 57 | C32: 11_神戸校 | D32: 57 | E32: 4.神戸校 | F32: 山本 虎太朗 | G32: ﾔﾏﾓﾄ ｺﾀﾛｳ | H32: 1 | I32: 674-0067 | J32: 兵庫県 | K32: 2027 | L32: 2027 | M32: 46277 | N32: H04 | O32: 58 | P32: 968 | Q32: 市役所・町役場等初級レベル | R32: 2 | S32: 2 | T32: 公務員 | U32: 1 | V32: 2780017 | W32: 0 | Z32: O | AA32: 46309 | AB32: 27 | AC32: 80017 | AD32: 57 | AE32: 11_神戸校 | AF32: 57 | AG32: 4.神戸校 | AH32: H04 | AI32: 58 | AJ32: 968 | AL32: 28117 | AM32: 県立 | AN32: 明石南 | AO32: 28 | AP32: 兵庫 | AQ32: 0 | AR32: Y | AT32: 現役 | AU32: R以外
A33: 2705750024 | B33: 57 | C33: 11_神戸校 | D33: 57 | E33: 4.神戸校 | F33: 河添 晴斗 | G33: ｶﾜｿﾞｴ ﾊﾙﾄ | H33: 1 | I33: 651-1233 | J33: 兵庫県 | K33: 2027 | L33: 2027 | M33: 46275 | N33: H04 | O33: 7 | P33: 266 | Q33: 税理士スタンダードコース | R33: 2 | S33: 1 | T33: 税理士会計士系 | U33: 3 | V33: 2780014 | W33: 0 | Z33: O | AA33: 46309 | AB33: 27 | AC33: 80014 | AD33: 57 | AE33: 11_神戸校 | AF33: 57 | AG33: 4.神戸校 | AH33: H04 | AI33: 7 | AJ33: 266 | AL33: 28032 | AM33: 私立 | AN33: 神戸星城 | AO33: 28 | AP33: 兵庫 | AQ33: 0 | AR33: Y | AT33: 現役 | AU33: R以外
A34: 2705750026 | B34: 57 | C34: 11_神戸校 | D34: 57 | E34: 4.神戸校 | F34: 中谷 留依 | G34: ﾅｶﾀﾆ ﾙｲ | H34: 2 | I34: 655-0006 | J34: 兵庫県 | K34: 2027 | L34: 2027 | M34: 46284 | N34: H04 | O34: 7 | P34: 266 | Q34: 税理士スタンダードコース | R34: 2 | S34: 1 | T34: 税理士会計士系 | U34: 3 | V34: 2780025 | W34: 0 | Z34: O | AA34: 46314 | AB34: 27 | AC34: 80025 | AD34: 57 | AE34: 11_神戸校 | AF34: 57 | AG34: 4.神戸校 | AH34: H04 | AI34: 7 | AJ34: 266 | AL34: 28030 | AM34: 県立 | AN34: 神戸商業 | AO34: 28 | AP34: 兵庫 | AQ34: 0 | AR34: Y | AT34: 現役 | AU34: R以外
A35: 2705750028 | B35: 57 | C35: 11_神戸校 | D35: 57 | E35: 4.神戸校 | F35: 原田 夕輝 | G35: ﾊﾗﾀﾞ ﾕｳｷ | H35: 1 | I35: 654-0026 | J35: 兵庫県 | K35: 0 | L35: 2027 | M35: 46269 | N35: H04 | O35: 57 | P35: 1775 | Q35: オフィスビジネス専攻コース | R35: 2 | S35: 3 | T35: ビジネス系 | U35: 4 | V35: 2780007 | W35: 0 | Z35: O | AA35: 46307 | AB35: 27 | AC35: 80007 | AD35: 57 | AE35: 11_神戸校 | AF35: 57 | AG35: 4.神戸校 | AH35: H04 | AI35: 57 | AJ35: 1775 | AL35: 28108 | AM35: 県立 | AN35: 農業 | AO35: 28 | AP35: 兵庫 | AQ35: 0 | AR35: Y | AT35: 現役以外 | AU35: R以外
A36: 2705750030 | B36: 57 | C36: 11_神戸校 | D36: 57 | E36: 4.神戸校 | F36: 辻 うらら | G36: ﾂｼﾞ ｳﾗﾗ | H36: 2 | I36: 676-0011 | J36: 兵庫県 | K36: 2027 | L36: 2027 | M36: 46296 | N36: H04 | O36: 0ｼ | P36: 121 | Q36: 医療事務コース | R36: 2 | S36: 8 | T36: 医療事務系 | U36: 6 | V36: 0 | W36: 0 | Z36: O | AB36: 0 | AC36: 0 | AD36: 0 | AE36: 0_未手続 | AG36: 0_未手続 | AJ36: 0 | AL36: 28200 | AM36: 県立 | AN36: 加古川南 | AO36: 28 | AP36: 兵庫 | AQ36: 0 | AR36: Y | AT36: 現役 | AU36: R以外
A37: 2705750031 | B37: 57 | C37: 11_神戸校 | D37: 57 | E37: 4.神戸校 | F37: 松本 航 | G37: ﾏﾂﾓﾄ ﾜﾀﾙ | H37: 1 | I37: 669-6701 | J37: 兵庫県 | K37: 2027 | L37: 2027 | M37: 46282 | N37: H04 | O37: 0ｽ | P37: 502 | Q37: スポーツトレーナーコース | R37: 2 | S37: 5 | T37: スポーツ系 | U37: 15 | V37: 2780026 | W37: 0 | Z37: O | AA37: 46314 | AB37: 27 | AC37: 80026 | AD37: 57 | AE37: 11_神戸校 | AF37: 57 | AG37: 4.神戸校 | AH37: H04 | AI37: 0ｽ | AJ37: 502 | AL37: 28231 | AM37: 県立 | AN37: 豊岡総合 | AO37: 28 | AP37: 兵庫 | AQ37: 0 | AR37: Y | AT37: 現役 | AU37: R以外
A38: 2705750033 | B38: 57 | C38: 11_神戸校 | D38: 57 | E38: 4.神戸校 | F38: 青山 桃果 | G38: ｱｵﾔﾏ ﾓﾓｶ | H38: 2 | I38: 651-1122 | J38: 兵庫県 | K38: 2027 | L38: 2027 | M38: 46271 | N38: H04 | O38: 58 | P38: 968 | Q38: 市役所・町役場等初級レベル | R38: 2 | S38: 2 | T38: 公務員 | U38: 1 | V38: 0 | W38: 0 | Z38: O | AB38: 0 | AC38: 0 | AD38: 0 | AE38: 0_未手続 | AG38: 0_未手続 | AJ38: 0 | AL38: 28245 | AM38: 県立 | AN38: 神戸鈴蘭台 | AO38: 28 | AP38: 兵庫 | AQ38: 0 | AR38: Y | AT38: 現役 | AU38: R以外
A39: 2705750034 | B39: 57 | C39: 11_神戸校 | D39: 57 | E39: 4.神戸校 | F39: 重本 全 | G39: ｼｹﾞﾓﾄ ｾﾞﾝ | H39: 1 | I39: 669-6831 | J39: 兵庫県 | K39: 2027 | L39: 2027 | M39: 46309 | N39: H04 | O39: 58 | P39: 428 | Q39: 消防官コース | R39: 2 | S39: 2 | T39: 公務員 | U39: 1 | V39: 0 | W39: 0 | Z39: O | AB39: 0 | AC39: 0 | AD39: 0 | AE39: 0_未手続 | AG39: 0_未手続 | AJ39: 0 | AL39: 31006 | AM39: 私立 | AN39: 鳥取城北 | AO39: 31 | AP39: 鳥取 | AQ39: 0 | AR39: Y | AT39: 現役 | AU39: R以外
A40: 2705750036 | B40: 57 | C40: 11_神戸校 | D40: 57 | E40: 4.神戸校 | F40: 捫垣 怜翔 | G40: ﾈｼﾞｶﾞｷ ﾚﾝﾄ | H40: 1 | I40: 651-1147 | J40: 兵庫県 | K40: 2027 | L40: 2027 | M40: 46313 | N40: H04 | O40: 58 | P40: 428 | Q40: 消防官コース | R40: 2 | S40: 2 | T40: 公務員 | U40: 1 | V40: 0 | W40: 0 | Z40: O | AB40: 0 | AC40: 0 | AD40: 0 | AE40: 0_未手続 | AG40: 0_未手続 | AJ40: 0 | AL40: 28022 | AM40: 私立 | AN40: 三田松聖 | AO40: 28 | AP40: 兵庫 | AQ40: 0 | AR40: Y | AT40: 現役 | AU40: R以外
...

Sheet 昨年比
A1: 出願＆手続き完了者集計（留学生含む） | G1: =日付設定!$B$1 -> 46534
A3: １．総計
B4: 神戸校 | E4: 姫路校
B5: 出願 | C5: 辞退者 | D5: 完了者 | E5: 出願 | F5: 辞退者 | G5: 完了者
